Workbook

Sheet README
B2: Customer Churn Analysis
B3: Telco Customer Churn Dataset — Executive Analytics Workbook
B5: Prepared by: | C5: Abdulmalik Abdulmalik · Stravionyx Ltd
B6: Date: | C6: June 21, 2026
B7: Dataset: | C7: 7,043 customer records · 21 source variables + 5 engineered fields
B9: Business Problem
B10: Which customers are likely to leave, and where should retention investment be focused first?
B12: Sheet Guide
B13: Raw Data | C13: Cleaned, formula-enriched customer-level data (source of all analysis in this workbook).
B14: Cleaning Log | C14: Documents every data quality check performed and the result.
B15: Dashboard | C15: One-page executive dashboard: Churn Rate, Customer Segments, Revenue at Risk.
B16: Churn by Contract | C16: Contract-type churn analysis with table and chart.
B17: Churn by Internet | C17: Internet service type churn analysis with table and chart.
B18: Churn by Payment | C18: Payment method churn analysis with table and chart.
B19: Churn by Charges | C19: Monthly charges quartile churn analysis with table and chart.
B20: Customer Segments | C20: Contract x Internet Service cross-tab identifying the highest-risk segment.
B21: Revenue at Risk | C21: Quantifies lost and at-risk monthly/annual revenue, with data validation scenario tool.
B22: Recommendations | C22: Retention strategies tied directly to findings.

Sheet Dashboard
B1: CUSTOMER CHURN — EXECUTIVE DASHBOARD
B2: Telco Customer Churn Dataset · 7,043 Customers · 21 Variables
B4: TOTAL CUSTOMERS | E4: CHURN RATE | H4: MONTHLY REVENUE LOST | K4: AT-RISK REVENUE (M2M)
B5: =COUNTA('Raw Data'!$A$2:$A$7044) | E5: =COUNTIF('Raw Data'!$U$2:$U$7044,"Yes")/COUNTA('Raw Data'!$U$2:$U$7044) | H5: =SUMIFS('Raw Data'!$S$2:$S$7044,'Raw Data'!$U$2:$U$7044,"Yes") | K5: =SUMIFS('Raw Data'!$S$2:$S$7044,'Raw Data'!$U$2:$U$7044,"No",'Raw Data'!$P$2:$P$7044,"Month-to-month")
B8: Highest-Risk Segment | E8: Riskiest Payment Method | H8: Safest Contract | K8: Annualized Revenue Lost
B9: Month-to-Month + Fiber (54.6%) | E9: Electronic Check (45.3%) | H9: Two Year (2.8%) | K9: =TEXT(SUMIFS('Raw Data'!$S$2:$S$7044,'Raw Data'!$U$2:$U$7044,"Yes")*12,"$#,##0")
B11: Interactive Filter — Select a Contract Type: | E11: All Contracts | I11: Filtered Headcount: | K11: =IF($E$11="All Contracts",COUNTA('Raw Data'!$A$2:$A$7044),COUNTIF('Raw Data'!$P$2:$P$7044,$E$11)) | L11: Filtered Churn Rate: | M11: =IF($E$11="All Contracts",COUNTIF('Raw Data'!$U$2:$U$7044,"Yes")/COUNTA('Raw Data'!$U$2:$U$7044),COUNTIFS('Raw Data'!$P$2:$P$7044,$E$11,'Raw Data'!$U$2:$U$7044,"Yes")/COUNTIF('Raw Data'!$P$2:$P$7044,$E$11))
B50: Prepared by Abdulmalik Abdulmalik · Stravionyx Ltd | Source: Telco Customer Churn Dataset | See 'Recommendations' tab for retention strategies

Sheet Customer Segments
B2: Customer Segments
B3: Contract × Internet Service cross-tab — identifies which customer segment carries the highest churn risk
B5: Contract | C5: Internet Service | D5: Total Customers | E5: Customers Churned | F5: Churn Rate | G5: Monthly Revenue | H5: Revenue at Risk | I5: Segment Label
B6: Month-to-month | C6: DSL | D6: =COUNTIFS('Raw Data'!$P$2:$P$7044,$B6,'Raw Data'!$I$2:$I$7044,$C6) | E6: =COUNTIFS('Raw Data'!$P$2:$P$7044,$B6,'Raw Data'!$I$2:$I$7044,$C6,'Raw Data'!$U$2:$U$7044,"Yes") | F6: =IFERROR(E6/D6,0) | G6: =SUMIFS('Raw Data'!$S$2:$S$7044,'Raw Data'!$P$2:$P$7044,$B6,'Raw Data'!$I$2:$I$7044,$C6) | H6: =SUMIFS('Raw Data'!$S$2:$S$7044,'Raw Data'!$P$2:$P$7044,$B6,'Raw Data'!$I$2:$I$7044,$C6,'Raw Data'!$U$2:$U$7044,"Yes") | I6: =B6&" / "&C6
B7: Month-to-month | C7: Fiber optic | D7: =COUNTIFS('Raw Data'!$P$2:$P$7044,$B7,'Raw Data'!$I$2:$I$7044,$C7) | E7: =COUNTIFS('Raw Data'!$P$2:$P$7044,$B7,'Raw Data'!$I$2:$I$7044,$C7,'Raw Data'!$U$2:$U$7044,"Yes") | F7: =IFERROR(E7/D7,0) | G7: =SUMIFS('Raw Data'!$S$2:$S$7044,'Raw Data'!$P$2:$P$7044,$B7,'Raw Data'!$I$2:$I$7044,$C7) | H7: =SUMIFS('Raw Data'!$S$2:$S$7044,'Raw Data'!$P$2:$P$7044,$B7,'Raw Data'!$I$2:$I$7044,$C7,'Raw Data'!$U$2:$U$7044,"Yes") | I7: =B7&" / "&C7
B8: Month-to-month | C8: No | D8: =COUNTIFS('Raw Data'!$P$2:$P$7044,$B8,'Raw Data'!$I$2:$I$7044,$C8) | E8: =COUNTIFS('Raw Data'!$P$2:$P$7044,$B8,'Raw Data'!$I$2:$I$7044,$C8,'Raw Data'!$U$2:$U$7044,"Yes") | F8: =IFERROR(E8/D8,0) | G8: =SUMIFS('Raw Data'!$S$2:$S$7044,'Raw Data'!$P$2:$P$7044,$B8,'Raw Data'!$I$2:$I$7044,$C8) | H8: =SUMIFS('Raw Data'!$S$2:$S$7044,'Raw Data'!$P$2:$P$7044,$B8,'Raw Data'!$I$2:$I$7044,$C8,'Raw Data'!$U$2:$U$7044,"Yes") | I8: =B8&" / "&C8
B9: One year | C9: DSL | D9: =COUNTIFS('Raw Data'!$P$2:$P$7044,$B9,'Raw Data'!$I$2:$I$7044,$C9) | E9: =COUNTIFS('Raw Data'!$P$2:$P$7044,$B9,'Raw Data'!$I$2:$I$7044,$C9,'Raw Data'!$U$2:$U$7044,"Yes") | F9: =IFERROR(E9/D9,0) | G9: =SUMIFS('Raw Data'!$S$2:$S$7044,'Raw Data'!$P$2:$P$7044,$B9,'Raw Data'!$I$2:$I$7044,$C9) | H9: =SUMIFS('Raw Data'!$S$2:$S$7044,'Raw Data'!$P$2:$P$7044,$B9,'Raw Data'!$I$2:$I$7044,$C9,'Raw Data'!$U$2:$U$7044,"Yes") | I9: =B9&" / "&C9
B10: One year | C10: Fiber optic | D10: =COUNTIFS('Raw Data'!$P$2:$P$7044,$B10,'Raw Data'!$I$2:$I$7044,$C10) | E10: =COUNTIFS('Raw Data'!$P$2:$P$7044,$B10,'Raw Data'!$I$2:$I$7044,$C10,'Raw Data'!$U$2:$U$7044,"Yes") | F10: =IFERROR(E10/D10,0) | G10: =SUMIFS('Raw Data'!$S$2:$S$7044,'Raw Data'!$P$2:$P$7044,$B10,'Raw Data'!$I$2:$I$7044,$C10) | H10: =SUMIFS('Raw Data'!$S$2:$S$7044,'Raw Data'!$P$2:$P$7044,$B10,'Raw Data'!$I$2:$I$7044,$C10,'Raw Data'!$U$2:$U$7044,"Yes") | I10: =B10&" / "&C10
B11: One year | C11: No | D11: =COUNTIFS('Raw Data'!$P$2:$P$7044,$B11,'Raw Data'!$I$2:$I$7044,$C11) | E11: =COUNTIFS('Raw Data'!$P$2:$P$7044,$B11,'Raw Data'!$I$2:$I$7044,$C11,'Raw Data'!$U$2:$U$7044,"Yes") | F11: =IFERROR(E11/D11,0) | G11: =SUMIFS('Raw Data'!$S$2:$S$7044,'Raw Data'!$P$2:$P$7044,$B11,'Raw Data'!$I$2:$I$7044,$C11) | H11: =SUMIFS('Raw Data'!$S$2:$S$7044,'Raw Data'!$P$2:$P$7044,$B11,'Raw Data'!$I$2:$I$7044,$C11,'Raw Data'!$U$2:$U$7044,"Yes") | I11: =B11&" / "&C11
B12: Two year | C12: DSL | D12: =COUNTIFS('Raw Data'!$P$2:$P$7044,$B12,'Raw Data'!$I$2:$I$7044,$C12) | E12: =COUNTIFS('Raw Data'!$P$2:$P$7044,$B12,'Raw Data'!$I$2:$I$7044,$C12,'Raw Data'!$U$2:$U$7044,"Yes") | F12: =IFERROR(E12/D12,0) | G12: =SUMIFS('Raw Data'!$S$2:$S$7044,'Raw Data'!$P$2:$P$7044,$B12,'Raw Data'!$I$2:$I$7044,$C12) | H12: =SUMIFS('Raw Data'!$S$2:$S$7044,'Raw Data'!$P$2:$P$7044,$B12,'Raw Data'!$I$2:$I$7044,$C12,'Raw Data'!$U$2:$U$7044,"Yes") | I12: =B12&" / "&C12
B13: Two year | C13: Fiber optic | D13: =COUNTIFS('Raw Data'!$P$2:$P$7044,$B13,'Raw Data'!$I$2:$I$7044,$C13) | E13: =COUNTIFS('Raw Data'!$P$2:$P$7044,$B13,'Raw Data'!$I$2:$I$7044,$C13,'Raw Data'!$U$2:$U$7044,"Yes") | F13: =IFERROR(E13/D13,0) | G13: =SUMIFS('Raw Data'!$S$2:$S$7044,'Raw Data'!$P$2:$P$7044,$B13,'Raw Data'!$I$2:$I$7044,$C13) | H13: =SUMIFS('Raw Data'!$S$2:$S$7044,'Raw Data'!$P$2:$P$7044,$B13,'Raw Data'!$I$2:$I$7044,$C13,'Raw Data'!$U$2:$U$7044,"Yes") | I13: =B13&" / "&C13
B14: Two year | C14: No | D14: =COUNTIFS('Raw Data'!$P$2:$P$7044,$B14,'Raw Data'!$I$2:$I$7044,$C14) | E14: =COUNTIFS('Raw Data'!$P$2:$P$7044,$B14,'Raw Data'!$I$2:$I$7044,$C14,'Raw Data'!$U$2:$U$7044,"Yes") | F14: =IFERROR(E14/D14,0) | G14: =SUMIFS('Raw Data'!$S$2:$S$7044,'Raw Data'!$P$2:$P$7044,$B14,'Raw Data'!$I$2:$I$7044,$C14) | H14: =SUMIFS('Raw Data'!$S$2:$S$7044,'Raw Data'!$P$2:$P$7044,$B14,'Raw Data'!$I$2:$I$7044,$C14,'Raw Data'!$U$2:$U$7044,"Yes") | I14: =B14&" / "&C14
B17: Highest-Risk Segment: | F17: Segment Churn Rate: | H17: Segment Monthly Revenue:
B18: =INDEX($B$6:$B$14,MATCH(MAX($F$6:$F$14),$F$6:$F$14,0))&" + "&INDEX($C$6:$C$14,MATCH(MAX($F$6:$F$14),$F$6:$F$14,0)) | F18: =MAX($F$6:$F$14) | H18: =INDEX($G$6:$G$14,MATCH(MAX($F$6:$F$14),$F$6:$F$14,0))
B21: Summary by Contract Type
B22: Contract | C22: Total Customers | D22: Churn Rate | E22: Monthly Revenue
B23: Month-to-month | C23: =COUNTIF('Raw Data'!$P$2:$P$7044,$B23) | D23: =COUNTIFS('Raw Data'!$P$2:$P$7044,$B23,'Raw Data'!$U$2:$U$7044,"Yes")/C23 | E23: =SUMIF('Raw Data'!$P$2:$P$7044,$B23,'Raw Data'!$S$2:$S$7044)
B24: One year | C24: =COUNTIF('Raw Data'!$P$2:$P$7044,$B24) | D24: =COUNTIFS('Raw Data'!$P$2:$P$7044,$B24,'Raw Data'!$U$2:$U$7044,"Yes")/C24 | E24: =SUMIF('Raw Data'!$P$2:$P$7044,$B24,'Raw Data'!$S$2:$S$7044)
B25: Two year | C25: =COUNTIF('Raw Data'!$P$2:$P$7044,$B25) | D25: =COUNTIFS('Raw Data'!$P$2:$P$7044,$B25,'Raw Data'!$U$2:$U$7044,"Yes")/C25 | E25: =SUMIF('Raw Data'!$P$2:$P$7044,$B25,'Raw Data'!$S$2:$S$7044)

Sheet Revenue at Risk
B2: Revenue at Risk
B3: Realized and forward-looking revenue exposure from customer churn
B5: MONTHLY REVENUE LOST (Already Churned) | E5: ANNUALIZED LOSS | H5: AT-RISK REVENUE (Active, Month-to-Month) | K5: % OF TOTAL REVENUE ALREADY LOST
B6: =SUMIFS('Raw Data'!$S$2:$S$7044,'Raw Data'!$U$2:$U$7044,"Yes") | E6: =SUMIFS('Raw Data'!$S$2:$S$7044,'Raw Data'!$U$2:$U$7044,"Yes")*12 | H6: =SUMIFS('Raw Data'!$S$2:$S$7044,'Raw Data'!$U$2:$U$7044,"No",'Raw Data'!$P$2:$P$7044,"Month-to-month") | K6: =SUMIFS('Raw Data'!$S$2:$S$7044,'Raw Data'!$U$2:$U$7044,"Yes")/SUM('Raw Data'!$S$2:$S$7044)
B9: Revenue at Risk by Driver
B10: Risk Driver | C10: At-Risk Customers (Active) | D10: Monthly Revenue Exposure | E10: Annualized Exposure
B11: Month-to-month contract | C11: =COUNTIFS('Raw Data'!$U$2:$U$7044,"No",'Raw Data'!$P$2:$P$7044,"Month-to-month") | D11: =SUMIFS('Raw Data'!$S$2:$S$7044,'Raw Data'!$U$2:$U$7044,"No",'Raw Data'!$P$2:$P$7044,"Month-to-month") | E11: =D11*12
B12: Fiber optic internet | C12: =COUNTIFS('Raw Data'!$U$2:$U$7044,"No",'Raw Data'!$I$2:$I$7044,"Fiber optic") | D12: =SUMIFS('Raw Data'!$S$2:$S$7044,'Raw Data'!$U$2:$U$7044,"No",'Raw Data'!$I$2:$I$7044,"Fiber optic") | E12: =D12*12
B13: Electronic check payment | C13: =COUNTIFS('Raw Data'!$U$2:$U$7044,"No",'Raw Data'!$R$2:$R$7044,"Electronic check") | D13: =SUMIFS('Raw Data'!$S$2:$S$7044,'Raw Data'!$U$2:$U$7044,"No",'Raw Data'!$R$2:$R$7044,"Electronic check") | E13: =D13*12
B14: No Tech Support | C14: =COUNTIFS('Raw Data'!$U$2:$U$7044,"No",'Raw Data'!$M$2:$M$7044,"No") | D14: =SUMIFS('Raw Data'!$S$2:$S$7044,'Raw Data'!$U$2:$U$7044,"No",'Raw Data'!$M$2:$M$7044,"No") | E14: =D14*12
B15: No Online Security | C15: =COUNTIFS('Raw Data'!$U$2:$U$7044,"No",'Raw Data'!$J$2:$J$7044,"No") | D15: =SUMIFS('Raw Data'!$S$2:$S$7044,'Raw Data'!$U$2:$U$7044,"No",'Raw Data'!$J$2:$J$7044,"No") | E15: =D15*12
B18: Retention Scenario Calculator
B19: Select a target segment and a hypothetical retention improvement to estimate monthly revenue saved.
B21: Target Segment: | D21: Month-to-month contract | H21: Segment Monthly Exposure: | J21: =INDEX($D$11:$D$15,MATCH($D$21,$B$11:$B$15,0))
B22: Assumed Retention Improvement: | D22: 0.1 | H22: Estimated Monthly Revenue Saved: | J22: =J21*$D$22
H23: Estimated Annualized Revenue Saved: | J23: =J22*12
I26: Revenue Status | J26: Monthly Revenue
I27: Already Lost (Churned) | J27: =SUMIFS('Raw Data'!$S$2:$S$7044,'Raw Data'!$U$2:$U$7044,"Yes")
I28: At-Risk (Active, Month-to-Month) | J28: =SUMIFS('Raw Data'!$S$2:$S$7044,'Raw Data'!$U$2:$U$7044,"No",'Raw Data'!$P$2:$P$7044,"Month-to-month")
I29: Stable (Active, Annual Contract) | J29: =SUMIFS('Raw Data'!$S$2:$S$7044,'Raw Data'!$U$2:$U$7044,"No",'Raw Data'!$P$2:$P$7044,"<>Month-to-month")

Sheet Recommendations
B2: Retention Strategies & Recommendations
B3: Evidence-based recommendations derived from the analysis in this workbook
B5: Area | C5: Evidence from Analysis | E5: Recommended Action
B6: 1. CONTRACT STRATEGY
B7: Migrate month-to-month customers onto term contracts | C7: Month-to-month customers churn at 42.7%, compared to 11.3% for one-year and just 2.8% for two-year contracts — a 15x gap between the riskiest and safest contract type. Month-to-month customers represent $136,447 in monthly revenue still active and exposed. | E7: Launch a structured contract conversion campaign offering a modest discount or value-add (e.g., one month free, premium support) in exchange for moving to a 1- or 2-year term. Prioritise customers with tenure under 12 months, where switching willingness is typically highest before habits set in.
B8: 2. HIGHEST-RISK SEGMENT
B9: Target Month-to-month + Fiber optic customers as the #1 priority segment | C9: This combined segment churns at 54.6%, the highest of any Contract × Internet Service combination, and represents $185,181 in monthly revenue — the single largest revenue pool in the dataset. | E9: Build a dedicated retention task force for this segment specifically. Combine contract conversion offers with service-quality outreach (proactive technical check-ins), since Fiber customers may be churning over price-to-value perception rather than contract terms alone.
B10: 3. PAYMENT METHOD
B11: Migrate Electronic Check payers to automatic payment methods | C11: Electronic check is both the most common payment method (2,365 customers) and the riskiest, churning at 45.3% — nearly 3x the rate of Credit Card (automatic) at 15.2%. | E11: Incentivise migration to automatic bank transfer or credit card payment (e.g., small bill credit for switching). Automatic payment removes a recurring manual decision point that correlates strongly with disengagement and churn.
B12: 4. SERVICE ADD-ONS AS RETENTION TOOLS
B13: Promote Tech Support and Online Security as standard inclusions | C13: Customers without Tech Support churn at 41.6% vs. 15.2% for those with it. Customers without Online Security churn at 41.8% vs. 14.6% for those with it — both among the largest churn gaps in the dataset. | E13: Bundle Tech Support and Online Security into entry-level plans at no extra cost, or offer a free 3-month trial to existing customers without these add-ons. The data suggests these services build engagement and perceived value, not just functional utility.
B14: 5. EARLY-TENURE ONBOARDING
B15: Strengthen onboarding for customers in their first 12 months | C15: Customers with 0-12 months tenure churn at 47.4%, more than double the second-highest tenure band (13-24 months at 28.7%), and nearly 5x the rate of customers with 49+ months tenure (9.5%). | E15: Implement a structured 90-day onboarding journey: welcome calls, proactive usage check-ins, and an early-warning flag for any new customer who hasn't activated key add-on services within the first 60 days.
B16: 6. PRICING & VALUE PERCEPTION
B17: Review pricing transparency for high-value customers | C17: Churned customers pay $74.44/month on average, $13 more than retained customers ($61.27/month). The 3rd charge quartile (mid-high pricing) has the highest churn rate of any quartile at 37.5%, higher even than the most expensive quartile. | E17: Investigate whether mid-to-high tier customers feel they're not getting proportional value. Consider tiered loyalty discounts or bundled value-adds specifically for the $70-$90/month price band rather than only top-tier customers.
B19: Note: All evidence figures in this sheet are drawn directly from the formulas in the Churn by Contract, Churn by Internet, Churn by Payment, Customer Segments, and Revenue at Risk tabs of this workbook.

Sheet Churn by Contract
B2: Churn by Contract Type
B3: Contract-type churn analysis — COUNTIFS / AVERAGEIF formulas reference Raw Data live
B5: Contract Type | C5: Total Customers | D5: Customers Churned | E5: Churn Rate | F5: Avg Monthly Charges | G5: Monthly Revenue at Risk | I5: Risk Flag
B6: Month-to-month | C6: =COUNTIF('Raw Data'!$P$2:$P$7044,$B6) | D6: =COUNTIFS('Raw Data'!$P$2:$P$7044,$B6,'Raw Data'!$U$2:$U$7044,"Yes") | E6: =D6/C6 | F6: =AVERAGEIF('Raw Data'!$P$2:$P$7044,$B6,'Raw Data'!$S$2:$S$7044) | G6: =SUMIFS('Raw Data'!$S$2:$S$7044,'Raw Data'!$P$2:$P$7044,$B6,'Raw Data'!$U$2:$U$7044,"Yes") | I6: =IFERROR(IF(E6>$E$9,"HIGH RISK","Normal"),"Normal")
B7: One year | C7: =COUNTIF('Raw Data'!$P$2:$P$7044,$B7) | D7: =COUNTIFS('Raw Data'!$P$2:$P$7044,$B7,'Raw Data'!$U$2:$U$7044,"Yes") | E7: =D7/C7 | F7: =AVERAGEIF('Raw Data'!$P$2:$P$7044,$B7,'Raw Data'!$S$2:$S$7044) | G7: =SUMIFS('Raw Data'!$S$2:$S$7044,'Raw Data'!$P$2:$P$7044,$B7,'Raw Data'!$U$2:$U$7044,"Yes") | I7: =IFERROR(IF(E7>$E$9,"HIGH RISK","Normal"),"Normal")
B8: Two year | C8: =COUNTIF('Raw Data'!$P$2:$P$7044,$B8) | D8: =COUNTIFS('Raw Data'!$P$2:$P$7044,$B8,'Raw Data'!$U$2:$U$7044,"Yes") | E8: =D8/C8 | F8: =AVERAGEIF('Raw Data'!$P$2:$P$7044,$B8,'Raw Data'!$S$2:$S$7044) | G8: =SUMIFS('Raw Data'!$S$2:$S$7044,'Raw Data'!$P$2:$P$7044,$B8,'Raw Data'!$U$2:$U$7044,"Yes") | I8: =IFERROR(IF(E8>$E$9,"HIGH RISK","Normal"),"Normal")
B9: TOTAL | C9: =SUM(C6:C8) | D9: =SUM(D6:D8) | E9: =D9/C9 | F9: =AVERAGE(F6:F8) | G9: =SUM(G6:G8)

Sheet Churn by Internet
B2: Churn by Internet Service
B3: Internet service type churn analysis — COUNTIFS / AVERAGEIF formulas reference Raw Data live
B5: Internet Service | C5: Total Customers | D5: Customers Churned | E5: Churn Rate | F5: Avg Monthly Charges | G5: Monthly Revenue at Risk | I5: Risk Flag
B6: DSL | C6: =COUNTIF('Raw Data'!$I$2:$I$7044,$B6) | D6: =COUNTIFS('Raw Data'!$I$2:$I$7044,$B6,'Raw Data'!$U$2:$U$7044,"Yes") | E6: =D6/C6 | F6: =AVERAGEIF('Raw Data'!$I$2:$I$7044,$B6,'Raw Data'!$S$2:$S$7044) | G6: =SUMIFS('Raw Data'!$S$2:$S$7044,'Raw Data'!$I$2:$I$7044,$B6,'Raw Data'!$U$2:$U$7044,"Yes") | I6: =IFERROR(IF(E6>$E$9,"HIGH RISK","Normal"),"Normal")
B7: Fiber optic | C7: =COUNTIF('Raw Data'!$I$2:$I$7044,$B7) | D7: =COUNTIFS('Raw Data'!$I$2:$I$7044,$B7,'Raw Data'!$U$2:$U$7044,"Yes") | E7: =D7/C7 | F7: =AVERAGEIF('Raw Data'!$I$2:$I$7044,$B7,'Raw Data'!$S$2:$S$7044) | G7: =SUMIFS('Raw Data'!$S$2:$S$7044,'Raw Data'!$I$2:$I$7044,$B7,'Raw Data'!$U$2:$U$7044,"Yes") | I7: =IFERROR(IF(E7>$E$9,"HIGH RISK","Normal"),"Normal")
B8: No | C8: =COUNTIF('Raw Data'!$I$2:$I$7044,$B8) | D8: =COUNTIFS('Raw Data'!$I$2:$I$7044,$B8,'Raw Data'!$U$2:$U$7044,"Yes") | E8: =D8/C8 | F8: =AVERAGEIF('Raw Data'!$I$2:$I$7044,$B8,'Raw Data'!$S$2:$S$7044) | G8: =SUMIFS('Raw Data'!$S$2:$S$7044,'Raw Data'!$I$2:$I$7044,$B8,'Raw Data'!$U$2:$U$7044,"Yes") | I8: =IFERROR(IF(E8>$E$9,"HIGH RISK","Normal"),"Normal")
B9: TOTAL | C9: =SUM(C6:C8) | D9: =SUM(D6:D8) | E9: =D9/C9 | F9: =AVERAGE(F6:F8) | G9: =SUM(G6:G8)

Sheet Churn by Payment
B2: Churn by Payment Method
B3: Payment method churn analysis — COUNTIFS / AVERAGEIF formulas reference Raw Data live
B5: Payment Method | C5: Total Customers | D5: Customers Churned | E5: Churn Rate | F5: Avg Monthly Charges | G5: Monthly Revenue at Risk | I5: Risk Flag
B6: Bank transfer (automatic) | C6: =COUNTIF('Raw Data'!$R$2:$R$7044,$B6) | D6: =COUNTIFS('Raw Data'!$R$2:$R$7044,$B6,'Raw Data'!$U$2:$U$7044,"Yes") | E6: =D6/C6 | F6: =AVERAGEIF('Raw Data'!$R$2:$R$7044,$B6,'Raw Data'!$S$2:$S$7044) | G6: =SUMIFS('Raw Data'!$S$2:$S$7044,'Raw Data'!$R$2:$R$7044,$B6,'Raw Data'!$U$2:$U$7044,"Yes") | I6: =IFERROR(IF(E6>$E$10,"HIGH RISK","Normal"),"Normal")
B7: Credit card (automatic) | C7: =COUNTIF('Raw Data'!$R$2:$R$7044,$B7) | D7: =COUNTIFS('Raw Data'!$R$2:$R$7044,$B7,'Raw Data'!$U$2:$U$7044,"Yes") | E7: =D7/C7 | F7: =AVERAGEIF('Raw Data'!$R$2:$R$7044,$B7,'Raw Data'!$S$2:$S$7044) | G7: =SUMIFS('Raw Data'!$S$2:$S$7044,'Raw Data'!$R$2:$R$7044,$B7,'Raw Data'!$U$2:$U$7044,"Yes") | I7: =IFERROR(IF(E7>$E$10,"HIGH RISK","Normal"),"Normal")
B8: Electronic check | C8: =COUNTIF('Raw Data'!$R$2:$R$7044,$B8) | D8: =COUNTIFS('Raw Data'!$R$2:$R$7044,$B8,'Raw Data'!$U$2:$U$7044,"Yes") | E8: =D8/C8 | F8: =AVERAGEIF('Raw Data'!$R$2:$R$7044,$B8,'Raw Data'!$S$2:$S$7044) | G8: =SUMIFS('Raw Data'!$S$2:$S$7044,'Raw Data'!$R$2:$R$7044,$B8,'Raw Data'!$U$2:$U$7044,"Yes") | I8: =IFERROR(IF(E8>$E$10,"HIGH RISK","Normal"),"Normal")
B9: Mailed check | C9: =COUNTIF('Raw Data'!$R$2:$R$7044,$B9) | D9: =COUNTIFS('Raw Data'!$R$2:$R$7044,$B9,'Raw Data'!$U$2:$U$7044,"Yes") | E9: =D9/C9 | F9: =AVERAGEIF('Raw Data'!$R$2:$R$7044,$B9,'Raw Data'!$S$2:$S$7044) | G9: =SUMIFS('Raw Data'!$S$2:$S$7044,'Raw Data'!$R$2:$R$7044,$B9,'Raw Data'!$U$2:$U$7044,"Yes") | I9: =IFERROR(IF(E9>$E$10,"HIGH RISK","Normal"),"Normal")
B10: TOTAL | C10: =SUM(C6:C9) | D10: =SUM(D6:D9) | E10: =D10/C10 | F10: =AVERAGE(F6:F9) | G10: =SUM(G6:G9)

Sheet Churn by Charges
B2: Churn by Monthly Charges Quartile
B3: Monthly charges quartile churn analysis — quartiles engineered via nested IF formulas in Raw Data
B5: Charge Band | C5: Total Customers | D5: Customers Churned | E5: Churn Rate | F5: Avg Monthly Charges | G5: Monthly Revenue at Risk | I5: Risk Flag
B6: Q1 Low | C6: =COUNTIF('Raw Data'!$X$2:$X$7044,$B6) | D6: =COUNTIFS('Raw Data'!$X$2:$X$7044,$B6,'Raw Data'!$U$2:$U$7044,"Yes") | E6: =D6/C6 | F6: =AVERAGEIF('Raw Data'!$X$2:$X$7044,$B6,'Raw Data'!$S$2:$S$7044) | G6: =SUMIFS('Raw Data'!$S$2:$S$7044,'Raw Data'!$X$2:$X$7044,$B6,'Raw Data'!$U$2:$U$7044,"Yes") | I6: =IFERROR(IF(E6>$E$10,"HIGH RISK","Normal"),"Normal")
B7: Q2 Mid-Low | C7: =COUNTIF('Raw Data'!$X$2:$X$7044,$B7) | D7: =COUNTIFS('Raw Data'!$X$2:$X$7044,$B7,'Raw Data'!$U$2:$U$7044,"Yes") | E7: =D7/C7 | F7: =AVERAGEIF('Raw Data'!$X$2:$X$7044,$B7,'Raw Data'!$S$2:$S$7044) | G7: =SUMIFS('Raw Data'!$S$2:$S$7044,'Raw Data'!$X$2:$X$7044,$B7,'Raw Data'!$U$2:$U$7044,"Yes") | I7: =IFERROR(IF(E7>$E$10,"HIGH RISK","Normal"),"Normal")
B8: Q3 Mid-High | C8: =COUNTIF('Raw Data'!$X$2:$X$7044,$B8) | D8: =COUNTIFS('Raw Data'!$X$2:$X$7044,$B8,'Raw Data'!$U$2:$U$7044,"Yes") | E8: =D8/C8 | F8: =AVERAGEIF('Raw Data'!$X$2:$X$7044,$B8,'Raw Data'!$S$2:$S$7044) | G8: =SUMIFS('Raw Data'!$S$2:$S$7044,'Raw Data'!$X$2:$X$7044,$B8,'Raw Data'!$U$2:$U$7044,"Yes") | I8: =IFERROR(IF(E8>$E$10,"HIGH RISK","Normal"),"Normal")
B9: Q4 High | C9: =COUNTIF('Raw Data'!$X$2:$X$7044,$B9) | D9: =COUNTIFS('Raw Data'!$X$2:$X$7044,$B9,'Raw Data'!$U$2:$U$7044,"Yes") | E9: =D9/C9 | F9: =AVERAGEIF('Raw Data'!$X$2:$X$7044,$B9,'Raw Data'!$S$2:$S$7044) | G9: =SUMIFS('Raw Data'!$S$2:$S$7044,'Raw Data'!$X$2:$X$7044,$B9,'Raw Data'!$U$2:$U$7044,"Yes") | I9: =IFERROR(IF(E9>$E$10,"HIGH RISK","Normal"),"Normal")
B10: TOTAL | C10: =SUM(C6:C9) | D10: =SUM(D6:D9) | E10: =D10/C10 | F10: =AVERAGE(F6:F9) | G10: =SUM(G6:G9)

Sheet Cleaning Log
B2: Data Cleaning Log
B3: Quality checks performed on the Telco Customer Churn dataset prior to analysis
B5: Check | C5: Method | D5: Result | E5: Action Taken
B6: Duplicate Records | C6: Full-row duplicate scan (.duplicated()) and customerID uniqueness check | D6: 0 duplicates found; 7,043 unique customerIDs | E6: No rows removed — dataset confirmed unique
B7: Missing Values (standard nulls) | C7: Null check across all 21 source columns | D7: 0 standard missing values | E7: No imputation required
B8: Hidden Missing Values — TotalCharges | C8: TotalCharges is stored as text; checked for blank/whitespace-only entries after trimming | D8: 11 records found with blank TotalCharges, all with tenure = 0 (brand-new customers not yet billed a full cycle) | E8: Built a Total Charges (Clean) formula column using IFERROR(VALUE(TRIM(...)), MonthlyCharges×tenure) so blank records resolve to $0 instead of breaking downstream SUM/AVERAGE formulas
B9: Data Type Validation | C9: Checked that MonthlyCharges is numeric and TotalCharges should be numeric but was stored as text | D9: MonthlyCharges: valid float64. TotalCharges: stored as text (str) due to the blank-string entries above | E9: Cleaned numeric version built in Raw Data; original text column retained for audit trail
B10: Negative / Invalid Numerics | C10: Checked tenure and MonthlyCharges for negative or zero-impossible values | D10: 0 invalid records — tenure ranges 0 to 72 months, MonthlyCharges ranges $18.25 to $118.75 | E10: All numeric fields confirmed within valid ranges
B11: Categorical Consistency | C11: Verified spelling/casing consistency across Contract, InternetService, PaymentMethod, Churn, and all service add-on columns | D11: 3 Contract types, 3 Internet Service types, 4 Payment Methods, binary Churn — all consistent, no typos or case mismatches | E11: No standardisation required
B12: Logical Consistency — Service Dependencies | C12: Checked that 'No internet service' values in OnlineSecurity, TechSupport, etc. align with InternetService = 'No' | D12: 1,526 customers with InternetService = 'No' consistently show 'No internet service' across all 6 dependent service columns | E12: No correction needed — dependent fields are internally consistent
B13: Data Validation Rules | C13: Applied dropdown validation to Contract and scenario-input cells on the Dashboard and Revenue at Risk sheets | D13: Validation lists applied | E13: Restricts filter and scenario inputs to valid category values only, preventing typo-driven errors
B14: Feature Engineering | C14: Built 5 new analysis fields directly in Excel using formulas | D14: Total Charges Clean (IFERROR/VALUE), Tenure Band (nested IF), Charge Band (nested IF on quartiles), Churn Flag (IF), Retention Risk Score (composite IF across 5 risk factors) | E14: All new fields are live formulas referencing Raw Data, fully auditable and dynamic
B16: Conclusion: | C16: The dataset passed all structural quality checks (no duplicates, no logical inconsistencies). The one significant finding was 11 records with hidden missing values in TotalCharges, caused by brand-new customers with zero tenure who had not yet been billed. This was resolved with a formula-driven fallback rather than row deletion, preserving the full 7,043-customer sample for analysis.

Sheet Raw Data
A1: customerID | B1: gender | C1: SeniorCitizen | D1: Partner | E1: Dependents | F1: tenure | G1: PhoneService | H1: MultipleLines | I1: InternetService | J1: OnlineSecurity | K1: OnlineBackup | L1: DeviceProtection | M1: TechSupport | N1: StreamingTV | O1: StreamingMovies | P1: Contract | Q1: PaperlessBilling | R1: PaymentMethod | S1: MonthlyCharges | T1: TotalCharges | U1: Churn | V1: Total Charges (Clean) | W1: Tenure Band | X1: Charge Band | Y1: Churn Flag | Z1: Retention Risk Score
A2: 7590-VHVEG | B2: Female | C2: 0 | D2: Yes | E2: No | F2: 1 | G2: No | H2: No phone service | I2: DSL | J2: No | K2: Yes | L2: No | M2: No | N2: No | O2: No | P2: Month-to-month | Q2: Yes | R2: Electronic check | S2: 29.85 | T2: 29.85 | U2: No | V2: =IFERROR(VALUE(TRIM(T2)),S2*F2) | W2: =IF(F2<=12,"0-12 mo",IF(F2<=24,"13-24 mo",IF(F2<=48,"25-48 mo","49+ mo"))) | X2: =IF(S2<=35.5,"Q1 Low",IF(S2<=70.35,"Q2 Mid-Low",IF(S2<=89.85,"Q3 Mid-High","Q4 High"))) | Y2: =IF(U2="Yes",1,0) | Z2: =IF(P2="Month-to-month",1,0)+IF(M2="No",1,0)+IF(J2="No",1,0)+IF(I2="Fiber optic",1,0)+IF(Q2="Yes",1,0)
A3: 5575-GNVDE | B3: Male | C3: 0 | D3: No | E3: No | F3: 34 | G3: Yes | H3: No | I3: DSL | J3: Yes | K3: No | L3: Yes | M3: No | N3: No | O3: No | P3: One year | Q3: No | R3: Mailed check | S3: 56.95 | T3: 1889.5 | U3: No | V3: =IFERROR(VALUE(TRIM(T3)),S3*F3) | W3: =IF(F3<=12,"0-12 mo",IF(F3<=24,"13-24 mo",IF(F3<=48,"25-48 mo","49+ mo"))) | X3: =IF(S3<=35.5,"Q1 Low",IF(S3<=70.35,"Q2 Mid-Low",IF(S3<=89.85,"Q3 Mid-High","Q4 High"))) | Y3: =IF(U3="Yes",1,0) | Z3: =IF(P3="Month-to-month",1,0)+IF(M3="No",1,0)+IF(J3="No",1,0)+IF(I3="Fiber optic",1,0)+IF(Q3="Yes",1,0)
A4: 3668-QPYBK | B4: Male | C4: 0 | D4: No | E4: No | F4: 2 | G4: Yes | H4: No | I4: DSL | J4: Yes | K4: Yes | L4: No | M4: No | N4: No | O4: No | P4: Month-to-month | Q4: Yes | R4: Mailed check | S4: 53.85 | T4: 108.15 | U4: Yes | V4: =IFERROR(VALUE(TRIM(T4)),S4*F4) | W4: =IF(F4<=12,"0-12 mo",IF(F4<=24,"13-24 mo",IF(F4<=48,"25-48 mo","49+ mo"))) | X4: =IF(S4<=35.5,"Q1 Low",IF(S4<=70.35,"Q2 Mid-Low",IF(S4<=89.85,"Q3 Mid-High","Q4 High"))) | Y4: =IF(U4="Yes",1,0) | Z4: =IF(P4="Month-to-month",1,0)+IF(M4="No",1,0)+IF(J4="No",1,0)+IF(I4="Fiber optic",1,0)+IF(Q4="Yes",1,0)
A5: 7795-CFOCW | B5: Male | C5: 0 | D5: No | E5: No | F5: 45 | G5: No | H5: No phone service | I5: DSL | J5: Yes | K5: No | L5: Yes | M5: Yes | N5: No | O5: No | P5: One year | Q5: No | R5: Bank transfer (automatic) | S5: 42.3 | T5: 1840.75 | U5: No | V5: =IFERROR(VALUE(TRIM(T5)),S5*F5) | W5: =IF(F5<=12,"0-12 mo",IF(F5<=24,"13-24 mo",IF(F5<=48,"25-48 mo","49+ mo"))) | X5: =IF(S5<=35.5,"Q1 Low",IF(S5<=70.35,"Q2 Mid-Low",IF(S5<=89.85,"Q3 Mid-High","Q4 High"))) | Y5: =IF(U5="Yes",1,0) | Z5: =IF(P5="Month-to-month",1,0)+IF(M5="No",1,0)+IF(J5="No",1,0)+IF(I5="Fiber optic",1,0)+IF(Q5="Yes",1,0)
A6: 9237-HQITU | B6: Female | C6: 0 | D6: No | E6: No | F6: 2 | G6: Yes | H6: No | I6: Fiber optic | J6: No | K6: No | L6: No | M6: No | N6: No | O6: No | P6: Month-to-month | Q6: Yes | R6: Electronic check | S6: 70.7 | T6: 151.65 | U6: Yes | V6: =IFERROR(VALUE(TRIM(T6)),S6*F6) | W6: =IF(F6<=12,"0-12 mo",IF(F6<=24,"13-24 mo",IF(F6<=48,"25-48 mo","49+ mo"))) | X6: =IF(S6<=35.5,"Q1 Low",IF(S6<=70.35,"Q2 Mid-Low",IF(S6<=89.85,"Q3 Mid-High","Q4 High"))) | Y6: =IF(U6="Yes",1,0) | Z6: =IF(P6="Month-to-month",1,0)+IF(M6="No",1,0)+IF(J6="No",1,0)+IF(I6="Fiber optic",1,0)+IF(Q6="Yes",1,0)
A7: 9305-CDSKC | B7: Female | C7: 0 | D7: No | E7: No | F7: 8 | G7: Yes | H7: Yes | I7: Fiber optic | J7: No | K7: No | L7: Yes | M7: No | N7: Yes | O7: Yes | P7: Month-to-month | Q7: Yes | R7: Electronic check | S7: 99.65 | T7: 820.5 | U7: Yes | V7: =IFERROR(VALUE(TRIM(T7)),S7*F7) | W7: =IF(F7<=12,"0-12 mo",IF(F7<=24,"13-24 mo",IF(F7<=48,"25-48 mo","49+ mo"))) | X7: =IF(S7<=35.5,"Q1 Low",IF(S7<=70.35,"Q2 Mid-Low",IF(S7<=89.85,"Q3 Mid-High","Q4 High"))) | Y7: =IF(U7="Yes",1,0) | Z7: =IF(P7="Month-to-month",1,0)+IF(M7="No",1,0)+IF(J7="No",1,0)+IF(I7="Fiber optic",1,0)+IF(Q7="Yes",1,0)
A8: 1452-KIOVK | B8: Male | C8: 0 | D8: No | E8: Yes | F8: 22 | G8: Yes | H8: Yes | I8: Fiber optic | J8: No | K8: Yes | L8: No | M8: No | N8: Yes | O8: No | P8: Month-to-month | Q8: Yes | R8: Credit card (automatic) | S8: 89.1 | T8: 1949.4 | U8: No | V8: =IFERROR(VALUE(TRIM(T8)),S8*F8) | W8: =IF(F8<=12,"0-12 mo",IF(F8<=24,"13-24 mo",IF(F8<=48,"25-48 mo","49+ mo"))) | X8: =IF(S8<=35.5,"Q1 Low",IF(S8<=70.35,"Q2 Mid-Low",IF(S8<=89.85,"Q3 Mid-High","Q4 High"))) | Y8: =IF(U8="Yes",1,0) | Z8: =IF(P8="Month-to-month",1,0)+IF(M8="No",1,0)+IF(J8="No",1,0)+IF(I8="Fiber optic",1,0)+IF(Q8="Yes",1,0)
A9: 6713-OKOMC | B9: Female | C9: 0 | D9: No | E9: No | F9: 10 | G9: No | H9: No phone service | I9: DSL | J9: Yes | K9: No | L9: No | M9: No | N9: No | O9: No | P9: Month-to-month | Q9: No | R9: Mailed check | S9: 29.75 | T9: 301.9 | U9: No | V9: =IFERROR(VALUE(TRIM(T9)),S9*F9) | W9: =IF(F9<=12,"0-12 mo",IF(F9<=24,"13-24 mo",IF(F9<=48,"25-48 mo","49+ mo"))) | X9: =IF(S9<=35.5,"Q1 Low",IF(S9<=70.35,"Q2 Mid-Low",IF(S9<=89.85,"Q3 Mid-High","Q4 High"))) | Y9: =IF(U9="Yes",1,0) | Z9: =IF(P9="Month-to-month",1,0)+IF(M9="No",1,0)+IF(J9="No",1,0)+IF(I9="Fiber optic",1,0)+IF(Q9="Yes",1,0)
A10: 7892-POOKP | B10: Female | C10: 0 | D10: Yes | E10: No | F10: 28 | G10: Yes | H10: Yes | I10: Fiber optic | J10: No | K10: No | L10: Yes | M10: Yes | N10: Yes | O10: Yes | P10: Month-to-month | Q10: Yes | R10: Electronic check | S10: 104.8 | T10: 3046.05 | U10: Yes | V10: =IFERROR(VALUE(TRIM(T10)),S10*F10) | W10: =IF(F10<=12,"0-12 mo",IF(F10<=24,"13-24 mo",IF(F10<=48,"25-48 mo","49+ mo"))) | X10: =IF(S10<=35.5,"Q1 Low",IF(S10<=70.35,"Q2 Mid-Low",IF(S10<=89.85,"Q3 Mid-High","Q4 High"))) | Y10: =IF(U10="Yes",1,0) | Z10: =IF(P10="Month-to-month",1,0)+IF(M10="No",1,0)+IF(J10="No",1,0)+IF(I10="Fiber optic",1,0)+IF(Q10="Yes",1,0)
A11: 6388-TABGU | B11: Male | C11: 0 | D11: No | E11: Yes | F11: 62 | G11: Yes | H11: No | I11: DSL | J11: Yes | K11: Yes | L11: No | M11: No | N11: No | O11: No | P11: One year | Q11: No | R11: Bank transfer (automatic) | S11: 56.15 | T11: 3487.95 | U11: No | V11: =IFERROR(VALUE(TRIM(T11)),S11*F11) | W11: =IF(F11<=12,"0-12 mo",IF(F11<=24,"13-24 mo",IF(F11<=48,"25-48 mo","49+ mo"))) | X11: =IF(S11<=35.5,"Q1 Low",IF(S11<=70.35,"Q2 Mid-Low",IF(S11<=89.85,"Q3 Mid-High","Q4 High"))) | Y11: =IF(U11="Yes",1,0) | Z11: =IF(P11="Month-to-month",1,0)+IF(M11="No",1,0)+IF(J11="No",1,0)+IF(I11="Fiber optic",1,0)+IF(Q11="Yes",1,0)
A12: 9763-GRSKD | B12: Male | C12: 0 | D12: Yes | E12: Yes | F12: 13 | G12: Yes | H12: No | I12: DSL | J12: Yes | K12: No | L12: No | M12: No | N12: No | O12: No | P12: Month-to-month | Q12: Yes | R12: Mailed check | S12: 49.95 | T12: 587.45 | U12: No | V12: =IFERROR(VALUE(TRIM(T12)),S12*F12) | W12: =IF(F12<=12,"0-12 mo",IF(F12<=24,"13-24 mo",IF(F12<=48,"25-48 mo","49+ mo"))) | X12: =IF(S12<=35.5,"Q1 Low",IF(S12<=70.35,"Q2 Mid-Low",IF(S12<=89.85,"Q3 Mid-High","Q4 High"))) | Y12: =IF(U12="Yes",1,0) | Z12: =IF(P12="Month-to-month",1,0)+IF(M12="No",1,0)+IF(J12="No",1,0)+IF(I12="Fiber optic",1,0)+IF(Q12="Yes",1,0)
A13: 7469-LKBCI | B13: Male | C13: 0 | D13: No | E13: No | F13: 16 | G13: Yes | H13: No | I13: No | J13: No internet service | K13: No internet service | L13: No internet service | M13: No internet service | N13: No internet service | O13: No internet service | P13: Two year | Q13: No | R13: Credit card (automatic) | S13: 18.95 | T13: 326.8 | U13: No | V13: =IFERROR(VALUE(TRIM(T13)),S13*F13) | W13: =IF(F13<=12,"0-12 mo",IF(F13<=24,"13-24 mo",IF(F13<=48,"25-48 mo","49+ mo"))) | X13: =IF(S13<=35.5,"Q1 Low",IF(S13<=70.35,"Q2 Mid-Low",IF(S13<=89.85,"Q3 Mid-High","Q4 High"))) | Y13: =IF(U13="Yes",1,0) | Z13: =IF(P13="Month-to-month",1,0)+IF(M13="No",1,0)+IF(J13="No",1,0)+IF(I13="Fiber optic",1,0)+IF(Q13="Yes",1,0)
... A489: 3649-JPUGY | B489: Male | C489: 0 | D489: No | E489: No | F489: 72 | G489: Yes | H489: Yes | I489: DSL | J489: No | K489: Yes | L489: Yes | M489: Yes | N489: Yes | O489: Yes | P489: Two year | Q489: Yes | R489: Bank transfer (automatic) | S489: 88.6 | T489: 6201.95 | U489: No | V489: =IFERROR(VALUE(TRIM(T489)),S489*F489) | W489: =IF(F489<=12,"0-12 mo",IF(F489<=24,"13-24 mo",IF(F489<=48,"25-48 mo","49+ mo"))) | X489: =IF(S489<=35.5,"Q1 Low",IF(S489<=70.35,"Q2 Mid-Low",IF(S489<=89.85,"Q3 Mid-High","Q4 High"))) | Y489: =IF(U489="Yes",1,0) | Z489: =IF(P489="Month-to-month",1,0)+IF(M489="No",1,0)+IF(J489="No",1,0)+IF(I489="Fiber optic",1,0)+IF(Q489="Yes",1,0)
A490: 4472-LVYGI | B490: Female | C490: 0 | D490: Yes | E490: Yes | F490: 0 | G490: No | H490: No phone service | I490: DSL | J490: Yes | K490: No | L490: Yes | M490: Yes | N490: Yes | O490: No | P490: Two year | Q490: Yes | R490: Bank transfer (automatic) | S490: 52.55 | U490: No | V490: =IFERROR(VALUE(TRIM(T490)),S490*F490) | W490: =IF(F490<=12,"0-12 mo",IF(F490<=24,"13-24 mo",IF(F490<=48,"25-48 mo","49+ mo"))) | X490: =IF(S490<=35.5,"Q1 Low",IF(S490<=70.35,"Q2 Mid-Low",IF(S490<=89.85,"Q3 Mid-High","Q4 High"))) | Y490: =IF(U490="Yes",1,0) | Z490: =IF(P490="Month-to-month",1,0)+IF(M490="No",1,0)+IF(J490="No",1,0)+IF(I490="Fiber optic",1,0)+IF(Q490="Yes",1,0)
A491: 8372-JUXUI | B491: Male | C491: 0 | D491: No | E491: Yes | F491: 1 | G491: Yes | H491: Yes | I491: Fiber optic | J491: No | K491: No | L491: No | M491: No | N491: No | O491: No | P491: Month-to-month | Q491: Yes | R491: Electronic check | S491: 74.35 | T491: 74.35 | U491: Yes | V491: =IFERROR(VALUE(TRIM(T491)),S491*F491) | W491: =IF(F491<=12,"0-12 mo",IF(F491<=24,"13-24 mo",IF(F491<=48,"25-48 mo","49+ mo"))) | X491: =IF(S491<=35.5,"Q1 Low",IF(S491<=70.35,"Q2 Mid-Low",IF(S491<=89.85,"Q3 Mid-High","Q4 High"))) | Y491: =IF(U491="Yes",1,0) | Z491: =IF(P491="Month-to-month",1,0)+IF(M491="No",1,0)+IF(J491="No",1,0)+IF(I491="Fiber optic",1,0)+IF(Q491="Yes",1,0)
A492: 3552-CTCYF | B492: Male | C492: 0 | D492: Yes | E492: Yes | F492: 63 | G492: Yes | H492: Yes | I492: Fiber optic | J492: No | K492: Yes | L492: Yes | M492: No | N492: Yes | O492: Yes | P492: Two year | Q492: Yes | R492: Bank transfer (automatic) | S492: 104.8 | T492: 6597.25 | U492: No | V492: =IFERROR(VALUE(TRIM(T492)),S492*F492) | W492: =IF(F492<=12,"0-12 mo",IF(F492<=24,"13-24 mo",IF(F492<=48,"25-48 mo","49+ mo"))) | X492: =IF(S492<=35.5,"Q1 Low",IF(S492<=70.35,"Q2 Mid-Low",IF(S492<=89.85,"Q3 Mid-High","Q4 High"))) | Y492: =IF(U492="Yes",1,0) | Z492: =IF(P492="Month-to-month",1,0)+IF(M492="No",1,0)+IF(J492="No",1,0)+IF(I492="Fiber optic",1,0)+IF(Q492="Yes",1,0)
A493: 6778-YSNIH | B493: Female | C493: 0 | D493: No | E493: No | F493: 2 | G493: Yes | H493: No | I493: DSL | J493: No | K493: Yes | L493: No | M493: No | N493: Yes | O493: No | P493: Month-to-month | Q493: Yes | R493: Electronic check | S493: 59 | T493: 114.15 | U493: No | V493: =IFERROR(VALUE(TRIM(T493)),S493*F493) | W493: =IF(F493<=12,"0-12 mo",IF(F493<=24,"13-24 mo",IF(F493<=48,"25-48 mo","49+ mo"))) | X493: =IF(S493<=35.5,"Q1 Low",IF(S493<=70.35,"Q2 Mid-Low",IF(S493<=89.85,"Q3 Mid-High","Q4 High"))) | Y493: =IF(U493="Yes",1,0) | Z493: =IF(P493="Month-to-month",1,0)+IF(M493="No",1,0)+IF(J493="No",1,0)+IF(I493="Fiber optic",1,0)+IF(Q493="Yes",1,0)
A494: 0388-EOPEX | B494: Female | C494: 0 | D494: Yes | E494: No | F494: 2 | G494: Yes | H494: No | I494: Fiber optic | J494: Yes | K494: No | L494: No | M494: No | N494: No | O494: No | P494: Month-to-month | Q494: Yes | R494: Electronic check | S494: 74.4 | T494: 139.4 | U494: Yes | V494: =IFERROR(VALUE(TRIM(T494)),S494*F494) | W494: =IF(F494<=12,"0-12 mo",IF(F494<=24,"13-24 mo",IF(F494<=48,"25-48 mo","49+ mo"))) | X494: =IF(S494<=35.5,"Q1 Low",IF(S494<=70.35,"Q2 Mid-Low",IF(S494<=89.85,"Q3 Mid-High","Q4 High"))) | Y494: =IF(U494="Yes",1,0) | Z494: =IF(P494="Month-to-month",1,0)+IF(M494="No",1,0)+IF(J494="No",1,0)+IF(I494="Fiber optic",1,0)+IF(Q494="Yes",1,0)
A495: 5756-OZRIO | B495: Male | C495: 1 | D495: Yes | E495: No | F495: 61 | G495: Yes | H495: Yes | I495: DSL | J495: No | K495: Yes | L495: No | M495: No | N495: No | O495: Yes | P495: One year | Q495: No | R495: Bank transfer (automatic) | S495: 64.05 | T495: 3902.6 | U495: No | V495: =IFERROR(VALUE(TRIM(T495)),S495*F495) | W495: =IF(F495<=12,"0-12 mo",IF(F495<=24,"13-24 mo",IF(F495<=48,"25-48 mo","49+ mo"))) | X495: =IF(S495<=35.5,"Q1 Low",IF(S495<=70.35,"Q2 Mid-Low",IF(S495<=89.85,"Q3 Mid-High","Q4 High"))) | Y495: =IF(U495="Yes",1,0) | Z495: =IF(P495="Month-to-month",1,0)+IF(M495="No",1,0)+IF(J495="No",1,0)+IF(I495="Fiber optic",1,0)+IF(Q495="Yes",1,0)
A496: 6579-JPICP | B496: Male | C496: 0 | D496: No | E496: No | F496: 1 | G496: Yes | H496: No | I496: No | J496: No internet service | K496: No internet service | L496: No internet service | M496: No internet service | N496: No internet service | O496: No internet service | P496: Month-to-month | Q496: No | R496: Mailed check | S496: 20.4 | T496: 20.4 | U496: No | V496: =IFERROR(VALUE(TRIM(T496)),S496*F496) | W496: =IF(F496<=12,"0-12 mo",IF(F496<=24,"13-24 mo",IF(F496<=48,"25-48 mo","49+ mo"))) | X496: =IF(S496<=35.5,"Q1 Low",IF(S496<=70.35,"Q2 Mid-Low",IF(S496<=89.85,"Q3 Mid-High","Q4 High"))) | Y496: =IF(U496="Yes",1,0) | Z496: =IF(P496="Month-to-month",1,0)+IF(M496="No",1,0)+IF(J496="No",1,0)+IF(I496="Fiber optic",1,0)+IF(Q496="Yes",1,0)
A497: 8205-OTCHB | B497: Male | C497: 0 | D497: No | E497: No | F497: 22 | G497: No | H497: No phone service | I497: DSL | J497: No | K497: Yes | L497: Yes | M497: No | N497: No | O497: Yes | P497: One year | Q497: Yes | R497: Bank transfer (automatic) | S497: 43.75 | T497: 903.6 | U497: Yes | V497: =IFERROR(VALUE(TRIM(T497)),S497*F497) | W497: =IF(F497<=12,"0-12 mo",IF(F497<=24,"13-24 mo",IF(F497<=48,"25-48 mo","49+ mo"))) | X497: =IF(S497<=35.5,"Q1 Low",IF(S497<=70.35,"Q2 Mid-Low",IF(S497<=89.85,"Q3 Mid-High","Q4 High"))) | Y497: =IF(U497="Yes",1,0) | Z497: =IF(P497="Month-to-month",1,0)+IF(M497="No",1,0)+IF(J497="No",1,0)+IF(I497="Fiber optic",1,0)+IF(Q497="Yes",1,0)
A498: 4134-BSXLX | B498: Male | C498: 0 | D498: Yes | E498: No | F498: 28 | G498: Yes | H498: No | I498: DSL | J498: Yes | K498: Yes | L498: No | M498: Yes | N498: No | O498: No | P498: Month-to-month | Q498: No | R498: Mailed check | S498: 60.9 | T498: 1785.65 | U498: No | V498: =IFERROR(VALUE(TRIM(T498)),S498*F498) | W498: =IF(F498<=12,"0-12 mo",IF(F498<=24,"13-24 mo",IF(F498<=48,"25-48 mo","49+ mo"))) | X498: =IF(S498<=35.5,"Q1 Low",IF(S498<=70.35,"Q2 Mid-Low",IF(S498<=89.85,"Q3 Mid-High","Q4 High"))) | Y498: =IF(U498="Yes",1,0) | Z498: =IF(P498="Month-to-month",1,0)+IF(M498="No",1,0)+IF(J498="No",1,0)+IF(I498="Fiber optic",1,0)+IF(Q498="Yes",1,0)
A499: 0505-SPOOW | B499: Female | C499: 0 | D499: Yes | E499: No | F499: 70 | G499: Yes | H499: No | I499: No | J499: No internet service | K499: No internet service | L499: No internet service | M499: No internet service | N499: No internet service | O499: No internet service | P499: Two year | Q499: No | R499: Bank transfer (automatic) | S499: 19.8 | T499: 1397.65 | U499: No | V499: =IFERROR(VALUE(TRIM(T499)),S499*F499) | W499: =IF(F499<=12,"0-12 mo",IF(F499<=24,"13-24 mo",IF(F499<=48,"25-48 mo","49+ mo"))) | X499: =IF(S499<=35.5,"Q1 Low",IF(S499<=70.35,"Q2 Mid-Low",IF(S499<=89.85,"Q3 Mid-High","Q4 High"))) | Y499: =IF(U499="Yes",1,0) | Z499: =IF(P499="Month-to-month",1,0)+IF(M499="No",1,0)+IF(J499="No",1,0)+IF(I499="Fiber optic",1,0)+IF(Q499="Yes",1,0)
A500: 6235-VDHOM | B500: Female | C500: 1 | D500: No | E500: No | F500: 5 | G500: No | H500: No phone service | I500: DSL | J500: No | K500: Yes | L500: No | M500: No | N500: No | O500: No | P500: Month-to-month | Q500: No | R500: Electronic check | S500: 28.45 | T500: 131.05 | U500: Yes | V500: =IFERROR(VALUE(TRIM(T500)),S500*F500) | W500: =IF(F500<=12,"0-12 mo",IF(F500<=24,"13-24 mo",IF(F500<=48,"25-48 mo","49+ mo"))) | X500: =IF(S500<=35.5,"Q1 Low",IF(S500<=70.35,"Q2 Mid-Low",IF(S500<=89.85,"Q3 Mid-High","Q4 High"))) | Y500: =IF(U500="Yes",1,0) | Z500: =IF(P500="Month-to-month",1,0)+IF(M500="No",1,0)+IF(J500="No",1,0)+IF(I500="Fiber optic",1,0)+IF(Q500="Yes",1,0)
A501: 7783-YKGDV | B501: Female | C501: 0 | D501: No | E501: No | F501: 12 | G501: Yes | H501: Yes | I501: Fiber optic | J501: Yes | K501: Yes | L501: Yes | M501: No | N501: No | O501: Yes | P501: Month-to-month | Q501: Yes | R501: Bank transfer (automatic) | S501: 99.7 | T501: 1238.45 | U501: Yes | V501: =IFERROR(VALUE(TRIM(T501)),S501*F501) | W501: =IF(F501<=12,"0-12 mo",IF(F501<=24,"13-24 mo",IF(F501<=48,"25-48 mo","49+ mo"))) | X501: =IF(S501<=35.5,"Q1 Low",IF(S501<=70.35,"Q2 Mid-Low",IF(S501<=89.85,"Q3 Mid-High","Q4 High"))) | Y501: =IF(U501="Yes",1,0) | Z501: =IF(P501="Month-to-month",1,0)+IF(M501="No",1,0)+IF(J501="No",1,0)+IF(I501="Fiber optic",1,0)+IF(Q501="Yes",1,0)
A502: 4374-YMUSQ | B502: Male | C502: 0 | D502: No | E502: No | F502: 34 | G502: Yes | H502: Yes | I502: Fiber optic | J502: Yes | K502: Yes | L502: Yes | M502: Yes | N502: Yes | O502: Yes | P502: One year | Q502: No | R502: Credit card (automatic) | S502: 116.25 | T502: 3899.05 | U502: No | V502: =IFERROR(VALUE(TRIM(T502)),S502*F502) | W502: =IF(F502<=12,"0-12 mo",IF(F502<=24,"13-24 mo",IF(F502<=48,"25-48 mo","49+ mo"))) | X502: =IF(S502<=35.5,"Q1 Low",IF(S502<=70.35,"Q2 Mid-Low",IF(S502<=89.85,"Q3 Mid-High","Q4 High"))) | Y502: =IF(U502="Yes",1,0) | Z502: =IF(P502="Month-to-month",1,0)+IF(M502="No",1,0)+IF(J502="No",1,0)+IF(I502="Fiber optic",1,0)+IF(Q502="Yes",1,0)
... A754: 1410-RSCMR | B754: Male | C754: 0 | D754: Yes | E754: Yes | F754: 7 | G754: Yes | H754: No | I754: DSL | J754: Yes | K754: No | L754: Yes | M754: Yes | N754: No | O754: Yes | P754: Month-to-month | Q754: Yes | R754: Credit card (automatic) | S754: 71.35 | T754: 515.75 | U754: No | V754: =IFERROR(VALUE(TRIM(T754)),S754*F754) | W754: =IF(F754<=12,"0-12 mo",IF(F754<=24,"13-24 mo",IF(F754<=48,"25-48 mo","49+ mo"))) | X754: =IF(S754<=35.5,"Q1 Low",IF(S754<=70.35,"Q2 Mid-Low",IF(S754<=89.85,"Q3 Mid-High","Q4 High"))) | Y754: =IF(U754="Yes",1,0) | Z754: =IF(P754="Month-to-month",1,0)+IF(M754="No",1,0)+IF(J754="No",1,0)+IF(I754="Fiber optic",1,0)+IF(Q754="Yes",1,0)
A755: 3115-CZMZD | B755: Male | C755: 0 | D755: No | E755: Yes | F755: 0 | G755: Yes | H755: No | I755: No | J755: No internet service | K755: No internet service | L755: No internet service | M755: No internet service | N755: No internet service | O755: No internet service | P755: Two year | Q755: No | R755: Mailed check | S755: 20.25 | U755: No | V755: =IFERROR(VALUE(TRIM(T755)),S755*F755) | W755: =IF(F755<=12,"0-12 mo",IF(F755<=24,"13-24 mo",IF(F755<=48,"25-48 mo","49+ mo"))) | X755: =IF(S755<=35.5,"Q1 Low",IF(S755<=70.35,"Q2 Mid-Low",IF(S755<=89.85,"Q3 Mid-High","Q4 High"))) | Y755: =IF(U755="Yes",1,0) | Z755: =IF(P755="Month-to-month",1,0)+IF(M755="No",1,0)+IF(J755="No",1,0)+IF(I755="Fiber optic",1,0)+IF(Q755="Yes",1,0)
A756: 0139-IVFJG | B756: Female | C756: 0 | D756: Yes | E756: No | F756: 2 | G756: Yes | H756: No | I756: Fiber optic | J756: Yes | K756: Yes | L756: No | M756: No | N756: Yes | O756: No | P756: Month-to-month | Q756: No | R756: Electronic check | S756: 90.35 | T756: 190.5 | U756: No | V756: =IFERROR(VALUE(TRIM(T756)),S756*F756) | W756: =IF(F756<=12,"0-12 mo",IF(F756<=24,"13-24 mo",IF(F756<=48,"25-48 mo","49+ mo"))) | X756: =IF(S756<=35.5,"Q1 Low",IF(S756<=70.35,"Q2 Mid-Low",IF(S756<=89.85,"Q3 Mid-High","Q4 High"))) | Y756: =IF(U756="Yes",1,0) | Z756: =IF(P756="Month-to-month",1,0)+IF(M756="No",1,0)+IF(J756="No",1,0)+IF(I756="Fiber optic",1,0)+IF(Q756="Yes",1,0)
A757: 6683-VLCTZ | B757: Male | C757: 1 | D757: No | E757: No | F757: 20 | G757: Yes | H757: Yes | I757: Fiber optic | J757: No | K757: No | L757: Yes | M757: No | N757: Yes | O757: Yes | P757: Month-to-month | Q757: Yes | R757: Electronic check | S757: 98.55 | T757: 1842.8 | U757: Yes | V757: =IFERROR(VALUE(TRIM(T757)),S757*F757) | W757: =IF(F757<=12,"0-12 mo",IF(F757<=24,"13-24 mo",IF(F757<=48,"25-48 mo","49+ mo"))) | X757: =IF(S757<=35.5,"Q1 Low",IF(S757<=70.35,"Q2 Mid-Low",IF(S757<=89.85,"Q3 Mid-High","Q4 High"))) | Y757: =IF(U757="Yes",1,0) | Z757: =IF(P757="Month-to-month",1,0)+IF(M757="No",1,0)+IF(J757="No",1,0)+IF(I757="Fiber optic",1,0)+IF(Q757="Yes",1,0)
A758: 5730-DBDSI | B758: Male | C758: 0 | D758: No | E758: No | F758: 66 | G758: Yes | H758: No | I758: No | J758: No internet service | K758: No internet service | L758: No internet service | M758: No internet service | N758: No internet service | O758: No internet service | P758: Two year | Q758: No | R758: Bank transfer (automatic) | S758: 19.7 | T758: 1253.8 | U758: No | V758: =IFERROR(VALUE(TRIM(T758)),S758*F758) | W758: =IF(F758<=12,"0-12 mo",IF(F758<=24,"13-24 mo",IF(F758<=48,"25-48 mo","49+ mo"))) | X758: =IF(S758<=35.5,"Q1 Low",IF(S758<=70.35,"Q2 Mid-Low",IF(S758<=89.85,"Q3 Mid-High","Q4 High"))) | Y758: =IF(U758="Yes",1,0) | Z758: =IF(P758="Month-to-month",1,0)+IF(M758="No",1,0)+IF(J758="No",1,0)+IF(I758="Fiber optic",1,0)+IF(Q758="Yes",1,0)
A759: 0030-FNXPP | B759: Female | C759: 0 | D759: No | E759: No | F759: 3 | G759: Yes | H759: No | I759: No | J759: No internet service | K759: No internet service | L759: No internet service | M759: No internet service | N759: No internet service | O759: No internet service | P759: Month-to-month | Q759: No | R759: Mailed check | S759: 19.85 | T759: 57.2 | U759: No | V759: =IFERROR(VALUE(TRIM(T759)),S759*F759) | W759: =IF(F759<=12,"0-12 mo",IF(F759<=24,"13-24 mo",IF(F759<=48,"25-48 mo","49+ mo"))) | X759: =IF(S759<=35.5,"Q1 Low",IF(S759<=70.35,"Q2 Mid-Low",IF(S759<=89.85,"Q3 Mid-High","Q4 High"))) | Y759: =IF(U759="Yes",1,0) | Z759: =IF(P759="Month-to-month",1,0)+IF(M759="No",1,0)+IF(J759="No",1,0)+IF(I759="Fiber optic",1,0)+IF(Q759="Yes",1,0)
A760: 2189-WWOEW | B760: Female | C760: 0 | D760: No | E760: Yes | F760: 15 | G760: Yes | H760: No | I760: Fiber optic | J760: No | K760: Yes | L760: No | M760: No | N760: No | O760: Yes | P760: Month-to-month | Q760: Yes | R760: Bank transfer (automatic) | S760: 85.9 | T760: 1269.55 | U760: Yes | V760: =IFERROR(VALUE(TRIM(T760)),S760*F760) | W760: =IF(F760<=12,"0-12 mo",IF(F760<=24,"13-24 mo",IF(F760<=48,"25-48 mo","49+ mo"))) | X760: =IF(S760<=35.5,"Q1 Low",IF(S760<=70.35,"Q2 Mid-Low",IF(S760<=89.85,"Q3 Mid-High","Q4 High"))) | Y760: =IF(U760="Yes",1,0) | Z760: =IF(P760="Month-to-month",1,0)+IF(M760="No",1,0)+IF(J760="No",1,0)+IF(I760="Fiber optic",1,0)+IF(Q760="Yes",1,0)
A761: 5684-FJVYR | B761: Female | C761: 0 | D761: Yes | E761: Yes | F761: 72 | G761: Yes | H761: Yes | I761: Fiber optic | J761: Yes | K761: Yes | L761: No | M761: Yes | N761: No | O761: No | P761: Two year | Q761: Yes | R761: Bank transfer (automatic) | S761: 90.35 | T761: 6563.4 | U761: No | V761: =IFERROR(VALUE(TRIM(T761)),S761*F761) | W761: =IF(F761<=12,"0-12 mo",IF(F761<=24,"13-24 mo",IF(F761<=48,"25-48 mo","49+ mo"))) | X761: =IF(S761<=35.5,"Q1 Low",IF(S761<=70.35,"Q2 Mid-Low",IF(S761<=89.85,"Q3 Mid-High","Q4 High"))) | Y761: =IF(U761="Yes",1,0) | Z761: =IF(P761="Month-to-month",1,0)+IF(M761="No",1,0)+IF(J761="No",1,0)+IF(I761="Fiber optic",1,0)+IF(Q761="Yes",1,0)
A762: 4013-GUXND | B762: Male | C762: 0 | D762: No | E762: No | F762: 1 | G762: Yes | H762: No | I762: No | J762: No internet service | K762: No internet service | L762: No internet service | M762: No internet service | N762: No internet service | O762: No internet service | P762: Month-to-month | Q762: No | R762: Mailed check | S762: 20.8 | T762: 20.8 | U762: No | V762: =IFERROR(VALUE(TRIM(T762)),S762*F762) | W762: =IF(F762<=12,"0-12 mo",IF(F762<=24,"13-24 mo",IF(F762<=48,"25-48 mo","49+ mo"))) | X762: =IF(S762<=35.5,"Q1 Low",IF(S762<=70.35,"Q2 Mid-Low",IF(S762<=89.85,"Q3 Mid-High","Q4 High"))) | Y762: =IF(U762="Yes",1,0) | Z762: =IF(P762="Month-to-month",1,0)+IF(M762="No",1,0)+IF(J762="No",1,0)+IF(I762="Fiber optic",1,0)+IF(Q762="Yes",1,0)
A763: 1894-IGFSG | B763: Female | C763: 0 | D763: No | E763: No | F763: 22 | G763: Yes | H763: No | I763: Fiber optic | J763: No | K763: No | L763: No | M763: No | N763: Yes | O763: Yes | P763: Month-to-month | Q763: No | R763: Electronic check | S763: 89.25 | T763: 1907.85 | U763: Yes | V763: =IFERROR(VALUE(TRIM(T763)),S763*F763) | W763: =IF(F763<=12,"0-12 mo",IF(F763<=24,"13-24 mo",IF(F763<=48,"25-48 mo","49+ mo"))) | X763: =IF(S763<=35.5,"Q1 Low",IF(S763<=70.35,"Q2 Mid-Low",IF(S763<=89.85,"Q3 Mid-High","Q4 High"))) | Y763: =IF(U763="Yes",1,0) | Z763: =IF(P763="Month-to-month",1,0)+IF(M763="No",1,0)+IF(J763="No",1,0)+IF(I763="Fiber optic",1,0)+IF(Q763="Yes",1,0)
A764: 7379-POKDZ | B764: Male | C764: 0 | D764: Yes | E764: No | F764: 3 | G764: Yes | H764: No | I764: Fiber optic | J764: No | K764: No | L764: No | M764: No | N764: No | O764: No | P764: Month-to-month | Q764: Yes | R764: Electronic check | S764: 70.3 | T764: 208.85 | U764: Yes | V764: =IFERROR(VALUE(TRIM(T764)),S764*F764) | W764: =IF(F764<=12,"0-12 mo",IF(F764<=24,"13-24 mo",IF(F764<=48,"25-48 mo","49+ mo"))) | X764: =IF(S764<=35.5,"Q1 Low",IF(S764<=70.35,"Q2 Mid-Low",IF(S764<=89.85,"Q3 Mid-High","Q4 High"))) | Y764: =IF(U764="Yes",1,0) | Z764: =IF(P764="Month-to-month",1,0)+IF(M764="No",1,0)+IF(J764="No",1,0)+IF(I764="Fiber optic",1,0)+IF(Q764="Yes",1,0)
A765: 1266-NZYUI | B765: Female | C765: 0 | D765: Yes | E765: Yes | F765: 72 | G765: Yes | H765: Yes | I765: DSL | J765: Yes | K765: No | L765: Yes | M765: Yes | N765: No | O765: No | P765: Two year | Q765: No | R765: Bank transfer (automatic) | S765: 66.85 | T765: 4758.8 | U765: No | V765: =IFERROR(VALUE(TRIM(T765)),S765*F765) | W765: =IF(F765<=12,"0-12 mo",IF(F765<=24,"13-24 mo",IF(F765<=48,"25-48 mo","49+ mo"))) | X765: =IF(S765<=35.5,"Q1 Low",IF(S765<=70.35,"Q2 Mid-Low",IF(S765<=89.85,"Q3 Mid-High","Q4 High"))) | Y765: =IF(U765="Yes",1,0) | Z765: =IF(P765="Month-to-month",1,0)+IF(M765="No",1,0)+IF(J765="No",1,0)+IF(I765="Fiber optic",1,0)+IF(Q765="Yes",1,0)
A766: 7969-FFOWG | B766: Male | C766: 0 | D766: Yes | E766: Yes | F766: 65 | G766: Yes | H766: No | I766: No | J766: No internet service | K766: No internet service | L766: No internet service | M766: No internet service | N766: No internet service | O766: No internet service | P766: Two year | Q766: No | R766: Mailed check | S766: 19.9 | T766: 1292.6 | U766: No | V766: =IFERROR(VALUE(TRIM(T766)),S766*F766) | W766: =IF(F766<=12,"0-12 mo",IF(F766<=24,"13-24 mo",IF(F766<=48,"25-48 mo","49+ mo"))) | X766: =IF(S766<=35.5,"Q1 Low",IF(S766<=70.35,"Q2 Mid-Low",IF(S766<=89.85,"Q3 Mid-High","Q4 High"))) | Y766: =IF(U766="Yes",1,0) | Z766: =IF(P766="Month-to-month",1,0)+IF(M766="No",1,0)+IF(J766="No",1,0)+IF(I766="Fiber optic",1,0)+IF(Q766="Yes",1,0)
...
