Workbook

Sheet README
B2: Supply Chain and Inventory Analysis
B3: Supply Chain Dataset — Executive Operations Workbook
B5: Prepared by: | C5: Abdulmalik Abdulmalik · Stravionyx Ltd
B6: Date: | C6: June 21, 2026
B7: Dataset: | C7: 100 SKUs · 24 source variables + 6 engineered fields
B9: Business Problem
B10: How can inventory management be improved by identifying delayed shipments, overstocked and understocked products, and underperforming suppliers?
B12: Sheet Guide
B13: Raw Data | C13: Cleaned, formula-enriched SKU-level data (source of all analysis in this workbook).
B14: Cleaning Log | C14: Documents every data quality check performed and the result.
B15: Dashboard | C15: One-page executive dashboard: delivery delays, supplier rankings, inventory health.
B16: Delayed Shipments | C16: Identifies and quantifies delayed shipments by carrier, route, and transport mode.
B17: Inventory Status | C17: Classifies every SKU as Overstocked, Understocked, or Healthy.
B18: Supplier Performance | C18: Ranks suppliers on defect rate, inspection pass rate, lead time, and cost.
B19: Recommendations | C19: Operational improvements tied directly to findings.

Sheet Dashboard
B1: SUPPLY CHAIN & INVENTORY — EXECUTIVE DASHBOARD
B2: Supply Chain Dataset · 100 SKUs · 5 Suppliers · 4 Transportation Modes
B4: DELAY RATE | E4: STOCKOUTS + UNDERSTOCKED | H4: OVERSTOCKED SKUS | K4: AVG SUPPLIER DEFECT RATE
B5: =COUNTIF('Raw Data'!$AA$2:$AA$101,"Delayed")/COUNTA('Raw Data'!$AA$2:$AA$101) | E5: =COUNTIF('Raw Data'!$Z$2:$Z$101,"STOCKOUT")+COUNTIF('Raw Data'!$Z$2:$Z$101,"Understocked") | H5: =COUNTIF('Raw Data'!$Z$2:$Z$101,"Overstocked") | K5: =AVERAGE('Raw Data'!$U$2:$U$101)
B8: Worst Carrier (Delay Rate) | E8: Top-Ranked Supplier | H8: Weakest Supplier (0% Pass Rate) | K8: SKUs Needing Immediate Action
B9: Carrier A (32.1%) | E9: Supplier 1 | H9: Supplier 4 | K9: =COUNTIF('Raw Data'!$Z$2:$Z$101,"STOCKOUT")&" Stockout, "&COUNTIF('Raw Data'!$Z$2:$Z$101,"Understocked")&" Understocked"
B11: Interactive Filter — Select a Product Type: | E11: All Products | I11: Filtered SKU Count: | K11: =IF($E$11="All Products",COUNTA('Raw Data'!$A$2:$A$101),COUNTIF('Raw Data'!$B$2:$B$101,$E$11)) | L11: Filtered Defect Rate: | M11: =IF($E$11="All Products",AVERAGE('Raw Data'!$U$2:$U$101),AVERAGEIF('Raw Data'!$B$2:$B$101,$E$11,'Raw Data'!$U$2:$U$101))
B50: Prepared by Abdulmalik Abdulmalik · Stravionyx Ltd | Source: Supply Chain Dataset | See 'Recommendations' tab for operational improvements

Sheet Delayed Shipments
B2: Delayed Shipments Analysis
B3: Shipments are classified Delayed when Shipping Times exceed 8 days (75th percentile benchmark — see Cleaning Log)
B5: TOTAL SHIPMENTS | E5: DELAYED SHIPMENTS | H5: DELAY RATE | K5: AVG DAYS OVER THRESHOLD
B6: =COUNTA('Raw Data'!$A$2:$A$101) | E6: =COUNTIF('Raw Data'!$AA$2:$AA$101,"Delayed") | H6: =COUNTIF('Raw Data'!$AA$2:$AA$101,"Delayed")/COUNTA('Raw Data'!$AA$2:$AA$101) | K6: =AVERAGEIF('Raw Data'!$AA$2:$AA$101,"Delayed",'Raw Data'!$AB$2:$AB$101)
B9: Delays by Shipping Carrier
B10: Carrier | C10: Total Shipments | D10: Delayed | E10: Delay Rate | F10: Avg Shipping Time | G10: Avg Shipping Cost
B11: Carrier A | C11: =COUNTIF('Raw Data'!$L$2:$L$101,$B11) | D11: =COUNTIFS('Raw Data'!$L$2:$L$101,$B11,'Raw Data'!$AA$2:$AA$101,"Delayed") | E11: =D11/C11 | F11: =AVERAGEIF('Raw Data'!$L$2:$L$101,$B11,'Raw Data'!$K$2:$K$101) | G11: =AVERAGEIF('Raw Data'!$L$2:$L$101,$B11,'Raw Data'!$M$2:$M$101)
B12: Carrier B | C12: =COUNTIF('Raw Data'!$L$2:$L$101,$B12) | D12: =COUNTIFS('Raw Data'!$L$2:$L$101,$B12,'Raw Data'!$AA$2:$AA$101,"Delayed") | E12: =D12/C12 | F12: =AVERAGEIF('Raw Data'!$L$2:$L$101,$B12,'Raw Data'!$K$2:$K$101) | G12: =AVERAGEIF('Raw Data'!$L$2:$L$101,$B12,'Raw Data'!$M$2:$M$101)
B13: Carrier C | C13: =COUNTIF('Raw Data'!$L$2:$L$101,$B13) | D13: =COUNTIFS('Raw Data'!$L$2:$L$101,$B13,'Raw Data'!$AA$2:$AA$101,"Delayed") | E13: =D13/C13 | F13: =AVERAGEIF('Raw Data'!$L$2:$L$101,$B13,'Raw Data'!$K$2:$K$101) | G13: =AVERAGEIF('Raw Data'!$L$2:$L$101,$B13,'Raw Data'!$M$2:$M$101)
I14: Delays by Transportation Mode
I15: Mode | J15: Total Shipments | K15: Delayed | L15: Delay Rate | M15: Avg Shipping Time
I16: Air | J16: =COUNTIF('Raw Data'!$V$2:$V$101,$I16) | K16: =COUNTIFS('Raw Data'!$V$2:$V$101,$I16,'Raw Data'!$AA$2:$AA$101,"Delayed") | L16: =K16/J16 | M16: =AVERAGEIF('Raw Data'!$V$2:$V$101,$I16,'Raw Data'!$K$2:$K$101)
I17: Rail | J17: =COUNTIF('Raw Data'!$V$2:$V$101,$I17) | K17: =COUNTIFS('Raw Data'!$V$2:$V$101,$I17,'Raw Data'!$AA$2:$AA$101,"Delayed") | L17: =K17/J17 | M17: =AVERAGEIF('Raw Data'!$V$2:$V$101,$I17,'Raw Data'!$K$2:$K$101)
I18: Road | J18: =COUNTIF('Raw Data'!$V$2:$V$101,$I18) | K18: =COUNTIFS('Raw Data'!$V$2:$V$101,$I18,'Raw Data'!$AA$2:$AA$101,"Delayed") | L18: =K18/J18 | M18: =AVERAGEIF('Raw Data'!$V$2:$V$101,$I18,'Raw Data'!$K$2:$K$101)
I19: Sea | J19: =COUNTIF('Raw Data'!$V$2:$V$101,$I19) | K19: =COUNTIFS('Raw Data'!$V$2:$V$101,$I19,'Raw Data'!$AA$2:$AA$101,"Delayed") | L19: =K19/J19 | M19: =AVERAGEIF('Raw Data'!$V$2:$V$101,$I19,'Raw Data'!$K$2:$K$101)
B31: Delays by Route
B32: Route | C32: Total Shipments | D32: Delayed | E32: Delay Rate | F32: Avg Shipping Time
B33: Route A | C33: =COUNTIF('Raw Data'!$W$2:$W$101,$B33) | D33: =COUNTIFS('Raw Data'!$W$2:$W$101,$B33,'Raw Data'!$AA$2:$AA$101,"Delayed") | E33: =D33/C33 | F33: =AVERAGEIF('Raw Data'!$W$2:$W$101,$B33,'Raw Data'!$K$2:$K$101)
B34: Route B | C34: =COUNTIF('Raw Data'!$W$2:$W$101,$B34) | D34: =COUNTIFS('Raw Data'!$W$2:$W$101,$B34,'Raw Data'!$AA$2:$AA$101,"Delayed") | E34: =D34/C34 | F34: =AVERAGEIF('Raw Data'!$W$2:$W$101,$B34,'Raw Data'!$K$2:$K$101)
B35: Route C | C35: =COUNTIF('Raw Data'!$W$2:$W$101,$B35) | D35: =COUNTIFS('Raw Data'!$W$2:$W$101,$B35,'Raw Data'!$AA$2:$AA$101,"Delayed") | E35: =D35/C35 | F35: =AVERAGEIF('Raw Data'!$W$2:$W$101,$B35,'Raw Data'!$K$2:$K$101)
B53: Delayed Shipments — Full List
B54: SKU | C54: Product Type | D54: Carrier | E54: Mode | F54: Route | G54: Shipping Time | H54: Days Over
B55: =INDEX('Raw Data'!$A$2:$A$101,MATCH("SKU22",'Raw Data'!$A$2:$A$101,0)) | C55: =INDEX('Raw Data'!$B$2:$B$101,MATCH("SKU22",'Raw Data'!$A$2:$A$101,0)) | D55: =INDEX('Raw Data'!$L$2:$L$101,MATCH("SKU22",'Raw Data'!$A$2:$A$101,0)) | E55: =INDEX('Raw Data'!$V$2:$V$101,MATCH("SKU22",'Raw Data'!$A$2:$A$101,0)) | F55: =INDEX('Raw Data'!$W$2:$W$101,MATCH("SKU22",'Raw Data'!$A$2:$A$101,0)) | G55: =INDEX('Raw Data'!$K$2:$K$101,MATCH("SKU22",'Raw Data'!$A$2:$A$101,0)) | H55: =INDEX('Raw Data'!$AB$2:$AB$101,MATCH("SKU22",'Raw Data'!$A$2:$A$101,0))
B56: =INDEX('Raw Data'!$A$2:$A$101,MATCH("SKU87",'Raw Data'!$A$2:$A$101,0)) | C56: =INDEX('Raw Data'!$B$2:$B$101,MATCH("SKU87",'Raw Data'!$A$2:$A$101,0)) | D56: =INDEX('Raw Data'!$L$2:$L$101,MATCH("SKU87",'Raw Data'!$A$2:$A$101,0)) | E56: =INDEX('Raw Data'!$V$2:$V$101,MATCH("SKU87",'Raw Data'!$A$2:$A$101,0)) | F56: =INDEX('Raw Data'!$W$2:$W$101,MATCH("SKU87",'Raw Data'!$A$2:$A$101,0)) | G56: =INDEX('Raw Data'!$K$2:$K$101,MATCH("SKU87",'Raw Data'!$A$2:$A$101,0)) | H56: =INDEX('Raw Data'!$AB$2:$AB$101,MATCH("SKU87",'Raw Data'!$A$2:$A$101,0))
B57: =INDEX('Raw Data'!$A$2:$A$101,MATCH("SKU50",'Raw Data'!$A$2:$A$101,0)) | C57: =INDEX('Raw Data'!$B$2:$B$101,MATCH("SKU50",'Raw Data'!$A$2:$A$101,0)) | D57: =INDEX('Raw Data'!$L$2:$L$101,MATCH("SKU50",'Raw Data'!$A$2:$A$101,0)) | E57: =INDEX('Raw Data'!$V$2:$V$101,MATCH("SKU50",'Raw Data'!$A$2:$A$101,0)) | F57: =INDEX('Raw Data'!$W$2:$W$101,MATCH("SKU50",'Raw Data'!$A$2:$A$101,0)) | G57: =INDEX('Raw Data'!$K$2:$K$101,MATCH("SKU50",'Raw Data'!$A$2:$A$101,0)) | H57: =INDEX('Raw Data'!$AB$2:$AB$101,MATCH("SKU50",'Raw Data'!$A$2:$A$101,0))
B58: =INDEX('Raw Data'!$A$2:$A$101,MATCH("SKU76",'Raw Data'!$A$2:$A$101,0)) | C58: =INDEX('Raw Data'!$B$2:$B$101,MATCH("SKU76",'Raw Data'!$A$2:$A$101,0)) | D58: =INDEX('Raw Data'!$L$2:$L$101,MATCH("SKU76",'Raw Data'!$A$2:$A$101,0)) | E58: =INDEX('Raw Data'!$V$2:$V$101,MATCH("SKU76",'Raw Data'!$A$2:$A$101,0)) | F58: =INDEX('Raw Data'!$W$2:$W$101,MATCH("SKU76",'Raw Data'!$A$2:$A$101,0)) | G58: =INDEX('Raw Data'!$K$2:$K$101,MATCH("SKU76",'Raw Data'!$A$2:$A$101,0)) | H58: =INDEX('Raw Data'!$AB$2:$AB$101,MATCH("SKU76",'Raw Data'!$A$2:$A$101,0))
B59: =INDEX('Raw Data'!$A$2:$A$101,MATCH("SKU75",'Raw Data'!$A$2:$A$101,0)) | C59: =INDEX('Raw Data'!$B$2:$B$101,MATCH("SKU75",'Raw Data'!$A$2:$A$101,0)) | D59: =INDEX('Raw Data'!$L$2:$L$101,MATCH("SKU75",'Raw Data'!$A$2:$A$101,0)) | E59: =INDEX('Raw Data'!$V$2:$V$101,MATCH("SKU75",'Raw Data'!$A$2:$A$101,0)) | F59: =INDEX('Raw Data'!$W$2:$W$101,MATCH("SKU75",'Raw Data'!$A$2:$A$101,0)) | G59: =INDEX('Raw Data'!$K$2:$K$101,MATCH("SKU75",'Raw Data'!$A$2:$A$101,0)) | H59: =INDEX('Raw Data'!$AB$2:$AB$101,MATCH("SKU75",'Raw Data'!$A$2:$A$101,0))
B60: =INDEX('Raw Data'!$A$2:$A$101,MATCH("SKU84",'Raw Data'!$A$2:$A$101,0)) | C60: =INDEX('Raw Data'!$B$2:$B$101,MATCH("SKU84",'Raw Data'!$A$2:$A$101,0)) | D60: =INDEX('Raw Data'!$L$2:$L$101,MATCH("SKU84",'Raw Data'!$A$2:$A$101,0)) | E60: =INDEX('Raw Data'!$V$2:$V$101,MATCH("SKU84",'Raw Data'!$A$2:$A$101,0)) | F60: =INDEX('Raw Data'!$W$2:$W$101,MATCH("SKU84",'Raw Data'!$A$2:$A$101,0)) | G60: =INDEX('Raw Data'!$K$2:$K$101,MATCH("SKU84",'Raw Data'!$A$2:$A$101,0)) | H60: =INDEX('Raw Data'!$AB$2:$AB$101,MATCH("SKU84",'Raw Data'!$A$2:$A$101,0))
B61: =INDEX('Raw Data'!$A$2:$A$101,MATCH("SKU13",'Raw Data'!$A$2:$A$101,0)) | C61: =INDEX('Raw Data'!$B$2:$B$101,MATCH("SKU13",'Raw Data'!$A$2:$A$101,0)) | D61: =INDEX('Raw Data'!$L$2:$L$101,MATCH("SKU13",'Raw Data'!$A$2:$A$101,0)) | E61: =INDEX('Raw Data'!$V$2:$V$101,MATCH("SKU13",'Raw Data'!$A$2:$A$101,0)) | F61: =INDEX('Raw Data'!$W$2:$W$101,MATCH("SKU13",'Raw Data'!$A$2:$A$101,0)) | G61: =INDEX('Raw Data'!$K$2:$K$101,MATCH("SKU13",'Raw Data'!$A$2:$A$101,0)) | H61: =INDEX('Raw Data'!$AB$2:$AB$101,MATCH("SKU13",'Raw Data'!$A$2:$A$101,0))
B62: =INDEX('Raw Data'!$A$2:$A$101,MATCH("SKU33",'Raw Data'!$A$2:$A$101,0)) | C62: =INDEX('Raw Data'!$B$2:$B$101,MATCH("SKU33",'Raw Data'!$A$2:$A$101,0)) | D62: =INDEX('Raw Data'!$L$2:$L$101,MATCH("SKU33",'Raw Data'!$A$2:$A$101,0)) | E62: =INDEX('Raw Data'!$V$2:$V$101,MATCH("SKU33",'Raw Data'!$A$2:$A$101,0)) | F62: =INDEX('Raw Data'!$W$2:$W$101,MATCH("SKU33",'Raw Data'!$A$2:$A$101,0)) | G62: =INDEX('Raw Data'!$K$2:$K$101,MATCH("SKU33",'Raw Data'!$A$2:$A$101,0)) | H62: =INDEX('Raw Data'!$AB$2:$AB$101,MATCH("SKU33",'Raw Data'!$A$2:$A$101,0))
B63: =INDEX('Raw Data'!$A$2:$A$101,MATCH("SKU17",'Raw Data'!$A$2:$A$101,0)) | C63: =INDEX('Raw Data'!$B$2:$B$101,MATCH("SKU17",'Raw Data'!$A$2:$A$101,0)) | D63: =INDEX('Raw Data'!$L$2:$L$101,MATCH("SKU17",'Raw Data'!$A$2:$A$101,0)) | E63: =INDEX('Raw Data'!$V$2:$V$101,MATCH("SKU17",'Raw Data'!$A$2:$A$101,0)) | F63: =INDEX('Raw Data'!$W$2:$W$101,MATCH("SKU17",'Raw Data'!$A$2:$A$101,0)) | G63: =INDEX('Raw Data'!$K$2:$K$101,MATCH("SKU17",'Raw Data'!$A$2:$A$101,0)) | H63: =INDEX('Raw Data'!$AB$2:$AB$101,MATCH("SKU17",'Raw Data'!$A$2:$A$101,0))
B64: =INDEX('Raw Data'!$A$2:$A$101,MATCH("SKU67",'Raw Data'!$A$2:$A$101,0)) | C64: =INDEX('Raw Data'!$B$2:$B$101,MATCH("SKU67",'Raw Data'!$A$2:$A$101,0)) | D64: =INDEX('Raw Data'!$L$2:$L$101,MATCH("SKU67",'Raw Data'!$A$2:$A$101,0)) | E64: =INDEX('Raw Data'!$V$2:$V$101,MATCH("SKU67",'Raw Data'!$A$2:$A$101,0)) | F64: =INDEX('Raw Data'!$W$2:$W$101,MATCH("SKU67",'Raw Data'!$A$2:$A$101,0)) | G64: =INDEX('Raw Data'!$K$2:$K$101,MATCH("SKU67",'Raw Data'!$A$2:$A$101,0)) | H64: =INDEX('Raw Data'!$AB$2:$AB$101,MATCH("SKU67",'Raw Data'!$A$2:$A$101,0))
B65: =INDEX('Raw Data'!$A$2:$A$101,MATCH("SKU47",'Raw Data'!$A$2:$A$101,0)) | C65: =INDEX('Raw Data'!$B$2:$B$101,MATCH("SKU47",'Raw Data'!$A$2:$A$101,0)) | D65: =INDEX('Raw Data'!$L$2:$L$101,MATCH("SKU47",'Raw Data'!$A$2:$A$101,0)) | E65: =INDEX('Raw Data'!$V$2:$V$101,MATCH("SKU47",'Raw Data'!$A$2:$A$101,0)) | F65: =INDEX('Raw Data'!$W$2:$W$101,MATCH("SKU47",'Raw Data'!$A$2:$A$101,0)) | G65: =INDEX('Raw Data'!$K$2:$K$101,MATCH("SKU47",'Raw Data'!$A$2:$A$101,0)) | H65: =INDEX('Raw Data'!$AB$2:$AB$101,MATCH("SKU47",'Raw Data'!$A$2:$A$101,0))
B66: =INDEX('Raw Data'!$A$2:$A$101,MATCH("SKU43",'Raw Data'!$A$2:$A$101,0)) | C66: =INDEX('Raw Data'!$B$2:$B$101,MATCH("SKU43",'Raw Data'!$A$2:$A$101,0)) | D66: =INDEX('Raw Data'!$L$2:$L$101,MATCH("SKU43",'Raw Data'!$A$2:$A$101,0)) | E66: =INDEX('Raw Data'!$V$2:$V$101,MATCH("SKU43",'Raw Data'!$A$2:$A$101,0)) | F66: =INDEX('Raw Data'!$W$2:$W$101,MATCH("SKU43",'Raw Data'!$A$2:$A$101,0)) | G66: =INDEX('Raw Data'!$K$2:$K$101,MATCH("SKU43",'Raw Data'!$A$2:$A$101,0)) | H66: =INDEX('Raw Data'!$AB$2:$AB$101,MATCH("SKU43",'Raw Data'!$A$2:$A$101,0))
B67: =INDEX('Raw Data'!$A$2:$A$101,MATCH("SKU37",'Raw Data'!$A$2:$A$101,0)) | C67: =INDEX('Raw Data'!$B$2:$B$101,MATCH("SKU37",'Raw Data'!$A$2:$A$101,0)) | D67: =INDEX('Raw Data'!$L$2:$L$101,MATCH("SKU37",'Raw Data'!$A$2:$A$101,0)) | E67: =INDEX('Raw Data'!$V$2:$V$101,MATCH("SKU37",'Raw Data'!$A$2:$A$101,0)) | F67: =INDEX('Raw Data'!$W$2:$W$101,MATCH("SKU37",'Raw Data'!$A$2:$A$101,0)) | G67: =INDEX('Raw Data'!$K$2:$K$101,MATCH("SKU37",'Raw Data'!$A$2:$A$101,0)) | H67: =INDEX('Raw Data'!$AB$2:$AB$101,MATCH("SKU37",'Raw Data'!$A$2:$A$101,0))
B68: =INDEX('Raw Data'!$A$2:$A$101,MATCH("SKU72",'Raw Data'!$A$2:$A$101,0)) | C68: =INDEX('Raw Data'!$B$2:$B$101,MATCH("SKU72",'Raw Data'!$A$2:$A$101,0)) | D68: =INDEX('Raw Data'!$L$2:$L$101,MATCH("SKU72",'Raw Data'!$A$2:$A$101,0)) | E68: =INDEX('Raw Data'!$V$2:$V$101,MATCH("SKU72",'Raw Data'!$A$2:$A$101,0)) | F68: =INDEX('Raw Data'!$W$2:$W$101,MATCH("SKU72",'Raw Data'!$A$2:$A$101,0)) | G68: =INDEX('Raw Data'!$K$2:$K$101,MATCH("SKU72",'Raw Data'!$A$2:$A$101,0)) | H68: =INDEX('Raw Data'!$AB$2:$AB$101,MATCH("SKU72",'Raw Data'!$A$2:$A$101,0))
B69: =INDEX('Raw Data'!$A$2:$A$101,MATCH("SKU94",'Raw Data'!$A$2:$A$101,0)) | C69: =INDEX('Raw Data'!$B$2:$B$101,MATCH("SKU94",'Raw Data'!$A$2:$A$101,0)) | D69: =INDEX('Raw Data'!$L$2:$L$101,MATCH("SKU94",'Raw Data'!$A$2:$A$101,0)) | E69: =INDEX('Raw Data'!$V$2:$V$101,MATCH("SKU94",'Raw Data'!$A$2:$A$101,0)) | F69: =INDEX('Raw Data'!$W$2:$W$101,MATCH("SKU94",'Raw Data'!$A$2:$A$101,0)) | G69: =INDEX('Raw Data'!$K$2:$K$101,MATCH("SKU94",'Raw Data'!$A$2:$A$101,0)) | H69: =INDEX('Raw Data'!$AB$2:$AB$101,MATCH("SKU94",'Raw Data'!$A$2:$A$101,0))
B70: =INDEX('Raw Data'!$A$2:$A$101,MATCH("SKU95",'Raw Data'!$A$2:$A$101,0)) | C70: =INDEX('Raw Data'!$B$2:$B$101,MATCH("SKU95",'Raw Data'!$A$2:$A$101,0)) | D70: =INDEX('Raw Data'!$L$2:$L$101,MATCH("SKU95",'Raw Data'!$A$2:$A$101,0)) | E70: =INDEX('Raw Data'!$V$2:$V$101,MATCH("SKU95",'Raw Data'!$A$2:$A$101,0)) | F70: =INDEX('Raw Data'!$W$2:$W$101,MATCH("SKU95",'Raw Data'!$A$2:$A$101,0)) | G70: =INDEX('Raw Data'!$K$2:$K$101,MATCH("SKU95",'Raw Data'!$A$2:$A$101,0)) | H70: =INDEX('Raw Data'!$AB$2:$AB$101,MATCH("SKU95",'Raw Data'!$A$2:$A$101,0))
B71: =INDEX('Raw Data'!$A$2:$A$101,MATCH("SKU97",'Raw Data'!$A$2:$A$101,0)) | C71: =INDEX('Raw Data'!$B$2:$B$101,MATCH("SKU97",'Raw Data'!$A$2:$A$101,0)) | D71: =INDEX('Raw Data'!$L$2:$L$101,MATCH("SKU97",'Raw Data'!$A$2:$A$101,0)) | E71: =INDEX('Raw Data'!$V$2:$V$101,MATCH("SKU97",'Raw Data'!$A$2:$A$101,0)) | F71: =INDEX('Raw Data'!$W$2:$W$101,MATCH("SKU97",'Raw Data'!$A$2:$A$101,0)) | G71: =INDEX('Raw Data'!$K$2:$K$101,MATCH("SKU97",'Raw Data'!$A$2:$A$101,0)) | H71: =INDEX('Raw Data'!$AB$2:$AB$101,MATCH("SKU97",'Raw Data'!$A$2:$A$101,0))

Sheet Inventory Status
B2: Inventory Status
B3: Every SKU classified as Stockout, Understocked, Healthy, or Overstocked based on Stock-to-Order Ratio
B5: STOCKOUTS | E5: UNDERSTOCKED | H5: OVERSTOCKED | K5: HEALTHY
B6: =COUNTIF('Raw Data'!$Z$2:$Z$101,"STOCKOUT") | E6: =COUNTIF('Raw Data'!$Z$2:$Z$101,"Understocked") | H6: =COUNTIF('Raw Data'!$Z$2:$Z$101,"Overstocked") | K6: =COUNTIF('Raw Data'!$Z$2:$Z$101,"Healthy")
B9: Inventory Status Summary
B10: Status | C10: SKU Count | D10: % of Total | E10: Avg Stock Level | F10: Avg Order Qty | G10: Total Revenue Exposure
B11: STOCKOUT | C11: =COUNTIF('Raw Data'!$Z$2:$Z$101,$B11) | D11: =C11/COUNTA('Raw Data'!$Z$2:$Z$101) | E11: =IFERROR(AVERAGEIF('Raw Data'!$Z$2:$Z$101,$B11,'Raw Data'!$H$2:$H$101),0) | F11: =IFERROR(AVERAGEIF('Raw Data'!$Z$2:$Z$101,$B11,'Raw Data'!$I$2:$I$101),0) | G11: =SUMIF('Raw Data'!$Z$2:$Z$101,$B11,'Raw Data'!$F$2:$F$101)
B12: Understocked | C12: =COUNTIF('Raw Data'!$Z$2:$Z$101,$B12) | D12: =C12/COUNTA('Raw Data'!$Z$2:$Z$101) | E12: =IFERROR(AVERAGEIF('Raw Data'!$Z$2:$Z$101,$B12,'Raw Data'!$H$2:$H$101),0) | F12: =IFERROR(AVERAGEIF('Raw Data'!$Z$2:$Z$101,$B12,'Raw Data'!$I$2:$I$101),0) | G12: =SUMIF('Raw Data'!$Z$2:$Z$101,$B12,'Raw Data'!$F$2:$F$101)
B13: Healthy | C13: =COUNTIF('Raw Data'!$Z$2:$Z$101,$B13) | D13: =C13/COUNTA('Raw Data'!$Z$2:$Z$101) | E13: =IFERROR(AVERAGEIF('Raw Data'!$Z$2:$Z$101,$B13,'Raw Data'!$H$2:$H$101),0) | F13: =IFERROR(AVERAGEIF('Raw Data'!$Z$2:$Z$101,$B13,'Raw Data'!$I$2:$I$101),0) | G13: =SUMIF('Raw Data'!$Z$2:$Z$101,$B13,'Raw Data'!$F$2:$F$101)
B14: Overstocked | C14: =COUNTIF('Raw Data'!$Z$2:$Z$101,$B14) | D14: =C14/COUNTA('Raw Data'!$Z$2:$Z$101) | E14: =IFERROR(AVERAGEIF('Raw Data'!$Z$2:$Z$101,$B14,'Raw Data'!$H$2:$H$101),0) | F14: =IFERROR(AVERAGEIF('Raw Data'!$Z$2:$Z$101,$B14,'Raw Data'!$I$2:$I$101),0) | G14: =SUMIF('Raw Data'!$Z$2:$Z$101,$B14,'Raw Data'!$F$2:$F$101)
I15: Inventory Status by Product Type
I16: Product Type | J16: Stockouts | K16: Understocked | L16: Healthy | M16: Overstocked
I17: cosmetics | J17: =COUNTIFS('Raw Data'!$B$2:$B$101,$I17,'Raw Data'!$Z$2:$Z$101,"STOCKOUT") | K17: =COUNTIFS('Raw Data'!$B$2:$B$101,$I17,'Raw Data'!$Z$2:$Z$101,"Understocked") | L17: =COUNTIFS('Raw Data'!$B$2:$B$101,$I17,'Raw Data'!$Z$2:$Z$101,"Healthy") | M17: =COUNTIFS('Raw Data'!$B$2:$B$101,$I17,'Raw Data'!$Z$2:$Z$101,"Overstocked")
I18: haircare | J18: =COUNTIFS('Raw Data'!$B$2:$B$101,$I18,'Raw Data'!$Z$2:$Z$101,"STOCKOUT") | K18: =COUNTIFS('Raw Data'!$B$2:$B$101,$I18,'Raw Data'!$Z$2:$Z$101,"Understocked") | L18: =COUNTIFS('Raw Data'!$B$2:$B$101,$I18,'Raw Data'!$Z$2:$Z$101,"Healthy") | M18: =COUNTIFS('Raw Data'!$B$2:$B$101,$I18,'Raw Data'!$Z$2:$Z$101,"Overstocked")
I19: skincare | J19: =COUNTIFS('Raw Data'!$B$2:$B$101,$I19,'Raw Data'!$Z$2:$Z$101,"STOCKOUT") | K19: =COUNTIFS('Raw Data'!$B$2:$B$101,$I19,'Raw Data'!$Z$2:$Z$101,"Understocked") | L19: =COUNTIFS('Raw Data'!$B$2:$B$101,$I19,'Raw Data'!$Z$2:$Z$101,"Healthy") | M19: =COUNTIFS('Raw Data'!$B$2:$B$101,$I19,'Raw Data'!$Z$2:$Z$101,"Overstocked")
B37: Priority Action List — Stockouts & Understocked SKUs
B38: SKU | C38: Product Type | D38: Status | E38: Stock Level | F38: Order Qty | G38: Revenue at Risk
B39: =INDEX('Raw Data'!$A$2:$A$101,MATCH("SKU68",'Raw Data'!$A$2:$A$101,0)) | C39: =INDEX('Raw Data'!$B$2:$B$101,MATCH("SKU68",'Raw Data'!$A$2:$A$101,0)) | D39: =INDEX('Raw Data'!$Z$2:$Z$101,MATCH("SKU68",'Raw Data'!$A$2:$A$101,0)) | E39: =INDEX('Raw Data'!$H$2:$H$101,MATCH("SKU68",'Raw Data'!$A$2:$A$101,0)) | F39: =INDEX('Raw Data'!$I$2:$I$101,MATCH("SKU68",'Raw Data'!$A$2:$A$101,0)) | G39: =INDEX('Raw Data'!$F$2:$F$101,MATCH("SKU68",'Raw Data'!$A$2:$A$101,0))
B40: =INDEX('Raw Data'!$A$2:$A$101,MATCH("SKU2",'Raw Data'!$A$2:$A$101,0)) | C40: =INDEX('Raw Data'!$B$2:$B$101,MATCH("SKU2",'Raw Data'!$A$2:$A$101,0)) | D40: =INDEX('Raw Data'!$Z$2:$Z$101,MATCH("SKU2",'Raw Data'!$A$2:$A$101,0)) | E40: =INDEX('Raw Data'!$H$2:$H$101,MATCH("SKU2",'Raw Data'!$A$2:$A$101,0)) | F40: =INDEX('Raw Data'!$I$2:$I$101,MATCH("SKU2",'Raw Data'!$A$2:$A$101,0)) | G40: =INDEX('Raw Data'!$F$2:$F$101,MATCH("SKU2",'Raw Data'!$A$2:$A$101,0))
B41: =INDEX('Raw Data'!$A$2:$A$101,MATCH("SKU34",'Raw Data'!$A$2:$A$101,0)) | C41: =INDEX('Raw Data'!$B$2:$B$101,MATCH("SKU34",'Raw Data'!$A$2:$A$101,0)) | D41: =INDEX('Raw Data'!$Z$2:$Z$101,MATCH("SKU34",'Raw Data'!$A$2:$A$101,0)) | E41: =INDEX('Raw Data'!$H$2:$H$101,MATCH("SKU34",'Raw Data'!$A$2:$A$101,0)) | F41: =INDEX('Raw Data'!$I$2:$I$101,MATCH("SKU34",'Raw Data'!$A$2:$A$101,0)) | G41: =INDEX('Raw Data'!$F$2:$F$101,MATCH("SKU34",'Raw Data'!$A$2:$A$101,0))
B42: =INDEX('Raw Data'!$A$2:$A$101,MATCH("SKU16",'Raw Data'!$A$2:$A$101,0)) | C42: =INDEX('Raw Data'!$B$2:$B$101,MATCH("SKU16",'Raw Data'!$A$2:$A$101,0)) | D42: =INDEX('Raw Data'!$Z$2:$Z$101,MATCH("SKU16",'Raw Data'!$A$2:$A$101,0)) | E42: =INDEX('Raw Data'!$H$2:$H$101,MATCH("SKU16",'Raw Data'!$A$2:$A$101,0)) | F42: =INDEX('Raw Data'!$I$2:$I$101,MATCH("SKU16",'Raw Data'!$A$2:$A$101,0)) | G42: =INDEX('Raw Data'!$F$2:$F$101,MATCH("SKU16",'Raw Data'!$A$2:$A$101,0))
B43: =INDEX('Raw Data'!$A$2:$A$101,MATCH("SKU47",'Raw Data'!$A$2:$A$101,0)) | C43: =INDEX('Raw Data'!$B$2:$B$101,MATCH("SKU47",'Raw Data'!$A$2:$A$101,0)) | D43: =INDEX('Raw Data'!$Z$2:$Z$101,MATCH("SKU47",'Raw Data'!$A$2:$A$101,0)) | E43: =INDEX('Raw Data'!$H$2:$H$101,MATCH("SKU47",'Raw Data'!$A$2:$A$101,0)) | F43: =INDEX('Raw Data'!$I$2:$I$101,MATCH("SKU47",'Raw Data'!$A$2:$A$101,0)) | G43: =INDEX('Raw Data'!$F$2:$F$101,MATCH("SKU47",'Raw Data'!$A$2:$A$101,0))
B44: =INDEX('Raw Data'!$A$2:$A$101,MATCH("SKU33",'Raw Data'!$A$2:$A$101,0)) | C44: =INDEX('Raw Data'!$B$2:$B$101,MATCH("SKU33",'Raw Data'!$A$2:$A$101,0)) | D44: =INDEX('Raw Data'!$Z$2:$Z$101,MATCH("SKU33",'Raw Data'!$A$2:$A$101,0)) | E44: =INDEX('Raw Data'!$H$2:$H$101,MATCH("SKU33",'Raw Data'!$A$2:$A$101,0)) | F44: =INDEX('Raw Data'!$I$2:$I$101,MATCH("SKU33",'Raw Data'!$A$2:$A$101,0)) | G44: =INDEX('Raw Data'!$F$2:$F$101,MATCH("SKU33",'Raw Data'!$A$2:$A$101,0))
B45: =INDEX('Raw Data'!$A$2:$A$101,MATCH("SKU4",'Raw Data'!$A$2:$A$101,0)) | C45: =INDEX('Raw Data'!$B$2:$B$101,MATCH("SKU4",'Raw Data'!$A$2:$A$101,0)) | D45: =INDEX('Raw Data'!$Z$2:$Z$101,MATCH("SKU4",'Raw Data'!$A$2:$A$101,0)) | E45: =INDEX('Raw Data'!$H$2:$H$101,MATCH("SKU4",'Raw Data'!$A$2:$A$101,0)) | F45: =INDEX('Raw Data'!$I$2:$I$101,MATCH("SKU4",'Raw Data'!$A$2:$A$101,0)) | G45: =INDEX('Raw Data'!$F$2:$F$101,MATCH("SKU4",'Raw Data'!$A$2:$A$101,0))
B46: =INDEX('Raw Data'!$A$2:$A$101,MATCH("SKU8",'Raw Data'!$A$2:$A$101,0)) | C46: =INDEX('Raw Data'!$B$2:$B$101,MATCH("SKU8",'Raw Data'!$A$2:$A$101,0)) | D46: =INDEX('Raw Data'!$Z$2:$Z$101,MATCH("SKU8",'Raw Data'!$A$2:$A$101,0)) | E46: =INDEX('Raw Data'!$H$2:$H$101,MATCH("SKU8",'Raw Data'!$A$2:$A$101,0)) | F46: =INDEX('Raw Data'!$I$2:$I$101,MATCH("SKU8",'Raw Data'!$A$2:$A$101,0)) | G46: =INDEX('Raw Data'!$F$2:$F$101,MATCH("SKU8",'Raw Data'!$A$2:$A$101,0))
B47: =INDEX('Raw Data'!$A$2:$A$101,MATCH("SKU87",'Raw Data'!$A$2:$A$101,0)) | C47: =INDEX('Raw Data'!$B$2:$B$101,MATCH("SKU87",'Raw Data'!$A$2:$A$101,0)) | D47: =INDEX('Raw Data'!$Z$2:$Z$101,MATCH("SKU87",'Raw Data'!$A$2:$A$101,0)) | E47: =INDEX('Raw Data'!$H$2:$H$101,MATCH("SKU87",'Raw Data'!$A$2:$A$101,0)) | F47: =INDEX('Raw Data'!$I$2:$I$101,MATCH("SKU87",'Raw Data'!$A$2:$A$101,0)) | G47: =INDEX('Raw Data'!$F$2:$F$101,MATCH("SKU87",'Raw Data'!$A$2:$A$101,0))
B48: =INDEX('Raw Data'!$A$2:$A$101,MATCH("SKU78",'Raw Data'!$A$2:$A$101,0)) | C48: =INDEX('Raw Data'!$B$2:$B$101,MATCH("SKU78",'Raw Data'!$A$2:$A$101,0)) | D48: =INDEX('Raw Data'!$Z$2:$Z$101,MATCH("SKU78",'Raw Data'!$A$2:$A$101,0)) | E48: =INDEX('Raw Data'!$H$2:$H$101,MATCH("SKU78",'Raw Data'!$A$2:$A$101,0)) | F48: =INDEX('Raw Data'!$I$2:$I$101,MATCH("SKU78",'Raw Data'!$A$2:$A$101,0)) | G48: =INDEX('Raw Data'!$F$2:$F$101,MATCH("SKU78",'Raw Data'!$A$2:$A$101,0))
B49: =INDEX('Raw Data'!$A$2:$A$101,MATCH("SKU57",'Raw Data'!$A$2:$A$101,0)) | C49: =INDEX('Raw Data'!$B$2:$B$101,MATCH("SKU57",'Raw Data'!$A$2:$A$101,0)) | D49: =INDEX('Raw Data'!$Z$2:$Z$101,MATCH("SKU57",'Raw Data'!$A$2:$A$101,0)) | E49: =INDEX('Raw Data'!$H$2:$H$101,MATCH("SKU57",'Raw Data'!$A$2:$A$101,0)) | F49: =INDEX('Raw Data'!$I$2:$I$101,MATCH("SKU57",'Raw Data'!$A$2:$A$101,0)) | G49: =INDEX('Raw Data'!$F$2:$F$101,MATCH("SKU57",'Raw Data'!$A$2:$A$101,0))
B50: =INDEX('Raw Data'!$A$2:$A$101,MATCH("SKU31",'Raw Data'!$A$2:$A$101,0)) | C50: =INDEX('Raw Data'!$B$2:$B$101,MATCH("SKU31",'Raw Data'!$A$2:$A$101,0)) | D50: =INDEX('Raw Data'!$Z$2:$Z$101,MATCH("SKU31",'Raw Data'!$A$2:$A$101,0)) | E50: =INDEX('Raw Data'!$H$2:$H$101,MATCH("SKU31",'Raw Data'!$A$2:$A$101,0)) | F50: =INDEX('Raw Data'!$I$2:$I$101,MATCH("SKU31",'Raw Data'!$A$2:$A$101,0)) | G50: =INDEX('Raw Data'!$F$2:$F$101,MATCH("SKU31",'Raw Data'!$A$2:$A$101,0))
B51: =INDEX('Raw Data'!$A$2:$A$101,MATCH("SKU15",'Raw Data'!$A$2:$A$101,0)) | C51: =INDEX('Raw Data'!$B$2:$B$101,MATCH("SKU15",'Raw Data'!$A$2:$A$101,0)) | D51: =INDEX('Raw Data'!$Z$2:$Z$101,MATCH("SKU15",'Raw Data'!$A$2:$A$101,0)) | E51: =INDEX('Raw Data'!$H$2:$H$101,MATCH("SKU15",'Raw Data'!$A$2:$A$101,0)) | F51: =INDEX('Raw Data'!$I$2:$I$101,MATCH("SKU15",'Raw Data'!$A$2:$A$101,0)) | G51: =INDEX('Raw Data'!$F$2:$F$101,MATCH("SKU15",'Raw Data'!$A$2:$A$101,0))
B52: =INDEX('Raw Data'!$A$2:$A$101,MATCH("SKU18",'Raw Data'!$A$2:$A$101,0)) | C52: =INDEX('Raw Data'!$B$2:$B$101,MATCH("SKU18",'Raw Data'!$A$2:$A$101,0)) | D52: =INDEX('Raw Data'!$Z$2:$Z$101,MATCH("SKU18",'Raw Data'!$A$2:$A$101,0)) | E52: =INDEX('Raw Data'!$H$2:$H$101,MATCH("SKU18",'Raw Data'!$A$2:$A$101,0)) | F52: =INDEX('Raw Data'!$I$2:$I$101,MATCH("SKU18",'Raw Data'!$A$2:$A$101,0)) | G52: =INDEX('Raw Data'!$F$2:$F$101,MATCH("SKU18",'Raw Data'!$A$2:$A$101,0))
B53: =INDEX('Raw Data'!$A$2:$A$101,MATCH("SKU58",'Raw Data'!$A$2:$A$101,0)) | C53: =INDEX('Raw Data'!$B$2:$B$101,MATCH("SKU58",'Raw Data'!$A$2:$A$101,0)) | D53: =INDEX('Raw Data'!$Z$2:$Z$101,MATCH("SKU58",'Raw Data'!$A$2:$A$101,0)) | E53: =INDEX('Raw Data'!$H$2:$H$101,MATCH("SKU58",'Raw Data'!$A$2:$A$101,0)) | F53: =INDEX('Raw Data'!$I$2:$I$101,MATCH("SKU58",'Raw Data'!$A$2:$A$101,0)) | G53: =INDEX('Raw Data'!$F$2:$F$101,MATCH("SKU58",'Raw Data'!$A$2:$A$101,0))
B54: =INDEX('Raw Data'!$A$2:$A$101,MATCH("SKU6",'Raw Data'!$A$2:$A$101,0)) | C54: =INDEX('Raw Data'!$B$2:$B$101,MATCH("SKU6",'Raw Data'!$A$2:$A$101,0)) | D54: =INDEX('Raw Data'!$Z$2:$Z$101,MATCH("SKU6",'Raw Data'!$A$2:$A$101,0)) | E54: =INDEX('Raw Data'!$H$2:$H$101,MATCH("SKU6",'Raw Data'!$A$2:$A$101,0)) | F54: =INDEX('Raw Data'!$I$2:$I$101,MATCH("SKU6",'Raw Data'!$A$2:$A$101,0)) | G54: =INDEX('Raw Data'!$F$2:$F$101,MATCH("SKU6",'Raw Data'!$A$2:$A$101,0))
B55: =INDEX('Raw Data'!$A$2:$A$101,MATCH("SKU67",'Raw Data'!$A$2:$A$101,0)) | C55: =INDEX('Raw Data'!$B$2:$B$101,MATCH("SKU67",'Raw Data'!$A$2:$A$101,0)) | D55: =INDEX('Raw Data'!$Z$2:$Z$101,MATCH("SKU67",'Raw Data'!$A$2:$A$101,0)) | E55: =INDEX('Raw Data'!$H$2:$H$101,MATCH("SKU67",'Raw Data'!$A$2:$A$101,0)) | F55: =INDEX('Raw Data'!$I$2:$I$101,MATCH("SKU67",'Raw Data'!$A$2:$A$101,0)) | G55: =INDEX('Raw Data'!$F$2:$F$101,MATCH("SKU67",'Raw Data'!$A$2:$A$101,0))
B56: =INDEX('Raw Data'!$A$2:$A$101,MATCH("SKU44",'Raw Data'!$A$2:$A$101,0)) | C56: =INDEX('Raw Data'!$B$2:$B$101,MATCH("SKU44",'Raw Data'!$A$2:$A$101,0)) | D56: =INDEX('Raw Data'!$Z$2:$Z$101,MATCH("SKU44",'Raw Data'!$A$2:$A$101,0)) | E56: =INDEX('Raw Data'!$H$2:$H$101,MATCH("SKU44",'Raw Data'!$A$2:$A$101,0)) | F56: =INDEX('Raw Data'!$I$2:$I$101,MATCH("SKU44",'Raw Data'!$A$2:$A$101,0)) | G56: =INDEX('Raw Data'!$F$2:$F$101,MATCH("SKU44",'Raw Data'!$A$2:$A$101,0))
B57: =INDEX('Raw Data'!$A$2:$A$101,MATCH("SKU9",'Raw Data'!$A$2:$A$101,0)) | C57: =INDEX('Raw Data'!$B$2:$B$101,MATCH("SKU9",'Raw Data'!$A$2:$A$101,0)) | D57: =INDEX('Raw Data'!$Z$2:$Z$101,MATCH("SKU9",'Raw Data'!$A$2:$A$101,0)) | E57: =INDEX('Raw Data'!$H$2:$H$101,MATCH("SKU9",'Raw Data'!$A$2:$A$101,0)) | F57: =INDEX('Raw Data'!$I$2:$I$101,MATCH("SKU9",'Raw Data'!$A$2:$A$101,0)) | G57: =INDEX('Raw Data'!$F$2:$F$101,MATCH("SKU9",'Raw Data'!$A$2:$A$101,0))
B58: =INDEX('Raw Data'!$A$2:$A$101,MATCH("SKU85",'Raw Data'!$A$2:$A$101,0)) | C58: =INDEX('Raw Data'!$B$2:$B$101,MATCH("SKU85",'Raw Data'!$A$2:$A$101,0)) | D58: =INDEX('Raw Data'!$Z$2:$Z$101,MATCH("SKU85",'Raw Data'!$A$2:$A$101,0)) | E58: =INDEX('Raw Data'!$H$2:$H$101,MATCH("SKU85",'Raw Data'!$A$2:$A$101,0)) | F58: =INDEX('Raw Data'!$I$2:$I$101,MATCH("SKU85",'Raw Data'!$A$2:$A$101,0)) | G58: =INDEX('Raw Data'!$F$2:$F$101,MATCH("SKU85",'Raw Data'!$A$2:$A$101,0))
B59: =INDEX('Raw Data'!$A$2:$A$101,MATCH("SKU75",'Raw Data'!$A$2:$A$101,0)) | C59: =INDEX('Raw Data'!$B$2:$B$101,MATCH("SKU75",'Raw Data'!$A$2:$A$101,0)) | D59: =INDEX('Raw Data'!$Z$2:$Z$101,MATCH("SKU75",'Raw Data'!$A$2:$A$101,0)) | E59: =INDEX('Raw Data'!$H$2:$H$101,MATCH("SKU75",'Raw Data'!$A$2:$A$101,0)) | F59: =INDEX('Raw Data'!$I$2:$I$101,MATCH("SKU75",'Raw Data'!$A$2:$A$101,0)) | G59: =INDEX('Raw Data'!$F$2:$F$101,MATCH("SKU75",'Raw Data'!$A$2:$A$101,0))
B60: =INDEX('Raw Data'!$A$2:$A$101,MATCH("SKU73",'Raw Data'!$A$2:$A$101,0)) | C60: =INDEX('Raw Data'!$B$2:$B$101,MATCH("SKU73",'Raw Data'!$A$2:$A$101,0)) | D60: =INDEX('Raw Data'!$Z$2:$Z$101,MATCH("SKU73",'Raw Data'!$A$2:$A$101,0)) | E60: =INDEX('Raw Data'!$H$2:$H$101,MATCH("SKU73",'Raw Data'!$A$2:$A$101,0)) | F60: =INDEX('Raw Data'!$I$2:$I$101,MATCH("SKU73",'Raw Data'!$A$2:$A$101,0)) | G60: =INDEX('Raw Data'!$F$2:$F$101,MATCH("SKU73",'Raw Data'!$A$2:$A$101,0))
B61: =INDEX('Raw Data'!$A$2:$A$101,MATCH("SKU42",'Raw Data'!$A$2:$A$101,0)) | C61: =INDEX('Raw Data'!$B$2:$B$101,MATCH("SKU42",'Raw Data'!$A$2:$A$101,0)) | D61: =INDEX('Raw Data'!$Z$2:$Z$101,MATCH("SKU42",'Raw Data'!$A$2:$A$101,0)) | E61: =INDEX('Raw Data'!$H$2:$H$101,MATCH("SKU42",'Raw Data'!$A$2:$A$101,0)) | F61: =INDEX('Raw Data'!$I$2:$I$101,MATCH("SKU42",'Raw Data'!$A$2:$A$101,0)) | G61: =INDEX('Raw Data'!$F$2:$F$101,MATCH("SKU42",'Raw Data'!$A$2:$A$101,0))
...

Sheet Supplier Performance
B2: Supplier Performance
B3: Suppliers ranked on quality, reliability, and cost — COUNTIFS / AVERAGEIF formulas reference Raw Data live
B5: Supplier | C5: SKUs Supplied | D5: Avg Defect Rate | E5: Inspections Passed | F5: Inspections Failed | G5: Pass Rate | H5: Avg Lead Time (days) | I5: Avg Shipping Time | J5: Total Cost | K5: Total Revenue | L5: Composite Score | M5: Rank
B6: Supplier 1 | C6: =COUNTIF('Raw Data'!$N$2:$N$101,$B6) | D6: =AVERAGEIF('Raw Data'!$N$2:$N$101,$B6,'Raw Data'!$U$2:$U$101) | E6: =COUNTIFS('Raw Data'!$N$2:$N$101,$B6,'Raw Data'!$T$2:$T$101,"Pass") | F6: =COUNTIFS('Raw Data'!$N$2:$N$101,$B6,'Raw Data'!$T$2:$T$101,"Fail") | G6: =IFERROR(E6/(E6+F6),0) | H6: =AVERAGEIF('Raw Data'!$N$2:$N$101,$B6,'Raw Data'!$P$2:$P$101) | I6: =AVERAGEIFS('Raw Data'!$K$2:$K$101,'Raw Data'!$N$2:$N$101,$B6) | J6: =SUMIF('Raw Data'!$N$2:$N$101,$B6,'Raw Data'!$X$2:$X$101) | K6: =SUMIF('Raw Data'!$N$2:$N$101,$B6,'Raw Data'!$F$2:$F$101) | L6: =(G6*50)+((1-D6/5)*30)+((1-H6/30)*20) | M6: =RANK(L6,$L$6:$L$10)
B7: Supplier 2 | C7: =COUNTIF('Raw Data'!$N$2:$N$101,$B7) | D7: =AVERAGEIF('Raw Data'!$N$2:$N$101,$B7,'Raw Data'!$U$2:$U$101) | E7: =COUNTIFS('Raw Data'!$N$2:$N$101,$B7,'Raw Data'!$T$2:$T$101,"Pass") | F7: =COUNTIFS('Raw Data'!$N$2:$N$101,$B7,'Raw Data'!$T$2:$T$101,"Fail") | G7: =IFERROR(E7/(E7+F7),0) | H7: =AVERAGEIF('Raw Data'!$N$2:$N$101,$B7,'Raw Data'!$P$2:$P$101) | I7: =AVERAGEIFS('Raw Data'!$K$2:$K$101,'Raw Data'!$N$2:$N$101,$B7) | J7: =SUMIF('Raw Data'!$N$2:$N$101,$B7,'Raw Data'!$X$2:$X$101) | K7: =SUMIF('Raw Data'!$N$2:$N$101,$B7,'Raw Data'!$F$2:$F$101) | L7: =(G7*50)+((1-D7/5)*30)+((1-H7/30)*20) | M7: =RANK(L7,$L$6:$L$10)
B8: Supplier 3 | C8: =COUNTIF('Raw Data'!$N$2:$N$101,$B8) | D8: =AVERAGEIF('Raw Data'!$N$2:$N$101,$B8,'Raw Data'!$U$2:$U$101) | E8: =COUNTIFS('Raw Data'!$N$2:$N$101,$B8,'Raw Data'!$T$2:$T$101,"Pass") | F8: =COUNTIFS('Raw Data'!$N$2:$N$101,$B8,'Raw Data'!$T$2:$T$101,"Fail") | G8: =IFERROR(E8/(E8+F8),0) | H8: =AVERAGEIF('Raw Data'!$N$2:$N$101,$B8,'Raw Data'!$P$2:$P$101) | I8: =AVERAGEIFS('Raw Data'!$K$2:$K$101,'Raw Data'!$N$2:$N$101,$B8) | J8: =SUMIF('Raw Data'!$N$2:$N$101,$B8,'Raw Data'!$X$2:$X$101) | K8: =SUMIF('Raw Data'!$N$2:$N$101,$B8,'Raw Data'!$F$2:$F$101) | L8: =(G8*50)+((1-D8/5)*30)+((1-H8/30)*20) | M8: =RANK(L8,$L$6:$L$10)
B9: Supplier 4 | C9: =COUNTIF('Raw Data'!$N$2:$N$101,$B9) | D9: =AVERAGEIF('Raw Data'!$N$2:$N$101,$B9,'Raw Data'!$U$2:$U$101) | E9: =COUNTIFS('Raw Data'!$N$2:$N$101,$B9,'Raw Data'!$T$2:$T$101,"Pass") | F9: =COUNTIFS('Raw Data'!$N$2:$N$101,$B9,'Raw Data'!$T$2:$T$101,"Fail") | G9: =IFERROR(E9/(E9+F9),0) | H9: =AVERAGEIF('Raw Data'!$N$2:$N$101,$B9,'Raw Data'!$P$2:$P$101) | I9: =AVERAGEIFS('Raw Data'!$K$2:$K$101,'Raw Data'!$N$2:$N$101,$B9) | J9: =SUMIF('Raw Data'!$N$2:$N$101,$B9,'Raw Data'!$X$2:$X$101) | K9: =SUMIF('Raw Data'!$N$2:$N$101,$B9,'Raw Data'!$F$2:$F$101) | L9: =(G9*50)+((1-D9/5)*30)+((1-H9/30)*20) | M9: =RANK(L9,$L$6:$L$10)
B10: Supplier 5 | C10: =COUNTIF('Raw Data'!$N$2:$N$101,$B10) | D10: =AVERAGEIF('Raw Data'!$N$2:$N$101,$B10,'Raw Data'!$U$2:$U$101) | E10: =COUNTIFS('Raw Data'!$N$2:$N$101,$B10,'Raw Data'!$T$2:$T$101,"Pass") | F10: =COUNTIFS('Raw Data'!$N$2:$N$101,$B10,'Raw Data'!$T$2:$T$101,"Fail") | G10: =IFERROR(E10/(E10+F10),0) | H10: =AVERAGEIF('Raw Data'!$N$2:$N$101,$B10,'Raw Data'!$P$2:$P$101) | I10: =AVERAGEIFS('Raw Data'!$K$2:$K$101,'Raw Data'!$N$2:$N$101,$B10) | J10: =SUMIF('Raw Data'!$N$2:$N$101,$B10,'Raw Data'!$X$2:$X$101) | K10: =SUMIF('Raw Data'!$N$2:$N$101,$B10,'Raw Data'!$F$2:$F$101) | L10: =(G10*50)+((1-D10/5)*30)+((1-H10/30)*20) | M10: =RANK(L10,$L$6:$L$10)
B13: Top-Ranked Supplier: | F13: Weakest Supplier (Quality Risk):
B14: =INDEX($B$6:$B$10,MATCH(1,$M$6:$M$10,0)) | F14: =INDEX($B$6:$B$10,MATCH(MAX($M$6:$M$10),$M$6:$M$10,0))

Sheet Recommendations
B2: Operational Recommendations
B3: Evidence-based recommendations derived from the analysis in this workbook
B5: Area | C5: Evidence from Analysis | E5: Recommended Action
B6: 1. SUPPLIER QUALITY
B7: Place Supplier 4 on a formal corrective action plan | C7: Supplier 4 has a 0% inspection pass rate across all 12 completed inspections (0 Pass, 12 Fail), the only supplier with zero passing inspections. This is the single most severe finding in the dataset. | E7: Suspend new purchase orders to Supplier 4 pending a root-cause quality audit. Require a documented corrective action plan and re-inspection of a sample batch before resuming orders. Evaluate alternate suppliers for the 18 SKUs currently sourced from Supplier 4.
B8: Expand volume with Supplier 1, the top-ranked supplier | C8: Supplier 1 leads on every quality dimension measured: lowest average defect rate (1.80%), highest inspection pass rate (68.4%), and the highest composite performance score of all 5 suppliers, while also generating the most revenue ($157,529). | E8: Negotiate expanded capacity and preferred-supplier terms with Supplier 1. Consider migrating a portion of Supplier 4's volume to Supplier 1 as quality issues are resolved.
B9: 2. SHIPPING & CARRIER STRATEGY
B10: Reduce reliance on Carrier A for time-sensitive shipments | C10: Carrier A has a 32.1% delay rate (9 of 28 shipments), more than 3x higher than Carrier B (9.3%) and more than 2x Carrier C (13.8%). Delayed shipments also cost 23% more on average than on-time shipments. | E10: Shift volume toward Carrier B where service allows. For shipments that must use Carrier A, build in additional buffer time or negotiate a service-level agreement with delay penalties.
B11: Reassess Sea and Rail transportation modes for time-critical routes | C11: Sea (7.1 days average) and Rail (6.6 days average) are the slowest transportation modes, compared to Road (4.7 days) and Air (5.1 days). | E11: Reserve Sea and Rail for non-urgent, high-volume, low-margin shipments. Route time-sensitive or high-value SKUs through Road or Air wherever the cost differential is justified by reduced delay risk.
B12: 3. INVENTORY REBALANCING
B13: Resolve the SKU68 stockout immediately | C13: SKU68 (haircare) has zero stock against 58 units on order — the only confirmed stockout in the dataset, representing an immediate fulfilment risk. | E13: Expedite replenishment for SKU68 as a priority order. Review safety stock policy for fast-moving haircare SKUs to prevent recurrence.
B14: Address the 24 understocked SKUs before they become stockouts | C14: 24 SKUs fall in the bottom quartile of stock-to-order ratio, meaning current stock covers a small fraction of outstanding order quantity — these are the next wave of stockout risk if not replenished. | E14: Use the Priority Action List on the Inventory Status tab to trigger reorder points for all 24 SKUs, ranked by lowest stock level first.
B15: Release working capital tied up in the 25 overstocked SKUs | C15: 25 SKUs carry stock-to-order ratios in the top quartile, including SKU74 (41 units in stock against just 1 unit on order) — capital sitting in inventory that isn't moving. | E15: Run a targeted clearance or bundling promotion on the most overstocked SKUs. Reduce future order quantities for these products and review forecasting assumptions that led to overordering.
B16: 4. PRODUCT-LEVEL FOCUS
B17: Prioritise inventory review for skincare, the highest-volume category | C17: Skincare has the most SKUs (40) and the highest total revenue ($241,628), but also a higher average defect rate (2.33%) than cosmetics (1.92%), making inventory and quality control here the highest-leverage area for improvement. | E17: Apply the supplier and carrier recommendations above with skincare SKUs as the first priority, given their outsized revenue contribution.
B19: Note: All evidence figures in this sheet are drawn directly from the formulas in the Delayed Shipments, Inventory Status, and Supplier Performance tabs of this workbook.

Sheet Cleaning Log
B2: Data Cleaning Log
B3: Quality checks performed on the Supply Chain dataset prior to analysis
B5: Check | C5: Method | D5: Result | E5: Action Taken
B6: Duplicate Records | C6: Full-row duplicate scan (.duplicated()) and SKU uniqueness check | D6: 0 duplicates found; 100 unique SKUs | E6: No rows removed — dataset confirmed unique
B7: Missing Values | C7: Null check across all 24 source columns | D7: 0 missing values | E7: No imputation required
B8: Negative / Invalid Numerics | C8: Checked Price, Stock levels, Lead times, Order quantities, Shipping times, and Defect rates for negative values | D8: 0 invalid records — all numeric fields within plausible operational ranges | E8: No correction needed
B9: Ambiguous Column Naming | C9: Identified two separately-named lead time columns: 'Lead times' (order-level) and 'Lead time' (supplier-level) | D9: Correlation between the two columns measured at -0.003 — confirming they are genuinely independent metrics, not duplicates | E9: Both columns retained as distinct; 'Lead time' is treated as the supplier/manufacturing lead time throughout this workbook, and 'Lead times' as the order-fulfilment lead time
B10: Categorical Consistency | C10: Verified spelling/casing consistency across Product type, Shipping carriers, Supplier name, Inspection results, Transportation modes, and Routes | D10: 3 Product types, 3 Carriers, 5 Suppliers, 3 Inspection outcomes, 4 Transport modes, 3 Routes — all consistent, no typos or case mismatches | E10: No standardisation required
B11: Stockout Detection | C11: Checked Stock levels = 0 | D11: 1 SKU (SKU68) found with zero stock against 58 units on order | E11: Flagged as STOCKOUT in the engineered Inventory Status field for priority action
B12: Delay Threshold Methodology | C12: No explicit promised-delivery-date field exists in the source data, so delay status was derived from Shipping times using the 75th percentile (8 days) as the operational benchmark | D12: 17 of 100 shipments (17%) classified as Delayed under this methodology | E12: Documented explicitly so the threshold can be recalibrated against actual SLA targets if/when available
B13: Feature Engineering | C13: Built 6 new analysis fields directly in Excel using formulas | D13: Stock-to-Order Ratio, Inventory Status (nested IF), Delayed Flag (IF), Days Over Threshold (MAX), Supplier Quality Score (composite IF), Cost per 1,000 Units Sold | E13: All new fields are live formulas referencing Raw Data, fully auditable and dynamic
B15: Conclusion: | C15: The dataset passed all structural quality checks (no duplicates, no missing values, no invalid numerics). The most important methodological note is that delay status is derived rather than directly observed, since no promised-delivery-date field exists in the source data; the 75th-percentile threshold used here should be replaced with actual SLA targets if they become available.

Sheet Raw Data
A1: SKU | B1: Product type | C1: Price | D1: Availability | E1: Number of products sold | F1: Revenue generated | G1: Customer demographics | H1: Stock levels | I1: Order quantities | J1: Lead times | K1: Shipping times | L1: Shipping carriers | M1: Shipping costs | N1: Supplier name | O1: Location | P1: Lead time | Q1: Production volumes | R1: Manufacturing lead time | S1: Manufacturing costs | T1: Inspection results | U1: Defect rates | V1: Transportation modes | W1: Routes | X1: Costs | Y1: Stock-to-Order Ratio | Z1: Inventory Status | AA1: Delayed Flag | AB1: Days Over Threshold | AC1: Supplier Quality Score | AD1: Total Cost per Unit
A2: SKU0 | B2: haircare | C2: 69.808006 | D2: 55 | E2: 802 | F2: 8661.9968 | G2: Non-binary | H2: 58 | I2: 96 | J2: 7 | K2: 4 | L2: Carrier B | M2: 2.9565721 | N2: Supplier 3 | O2: Mumbai | P2: 29 | Q2: 215 | R2: 29 | S2: 46.279879 | T2: Pending | U2: 0.22641036 | V2: Road | W2: Route B | X2: 187.75208 | Y2: =IFERROR(H2/I2,0) | Z2: =IF(H2=0,"STOCKOUT",IF(Y2>=1.933,"Overstocked",IF(Y2<=0.3889,"Understocked","Healthy"))) | AA2: =IF(K2>8,"Delayed","On Time") | AB2: =MAX(0,K2-8) | AC2: =IF(T2="Pass",2,IF(T2="Pending",1,0))-(U2/5) | AD2: =IFERROR(X2/E2*1000,0)
A3: SKU1 | B3: skincare | C3: 14.843523 | D3: 95 | E3: 736 | F3: 7460.9001 | G3: Female | H3: 53 | I3: 37 | J3: 30 | K3: 2 | L3: Carrier A | M3: 9.7165748 | N3: Supplier 3 | O3: Mumbai | P3: 23 | Q3: 517 | R3: 30 | S3: 33.616769 | T3: Pending | U3: 4.854068 | V3: Road | W3: Route B | X3: 503.06558 | Y3: =IFERROR(H3/I3,0) | Z3: =IF(H3=0,"STOCKOUT",IF(Y3>=1.933,"Overstocked",IF(Y3<=0.3889,"Understocked","Healthy"))) | AA3: =IF(K3>8,"Delayed","On Time") | AB3: =MAX(0,K3-8) | AC3: =IF(T3="Pass",2,IF(T3="Pending",1,0))-(U3/5) | AD3: =IFERROR(X3/E3*1000,0)
A4: SKU2 | B4: haircare | C4: 11.319683 | D4: 34 | E4: 8 | F4: 9577.7496 | G4: Unknown | H4: 1 | I4: 88 | J4: 10 | K4: 2 | L4: Carrier B | M4: 8.0544793 | N4: Supplier 1 | O4: Mumbai | P4: 12 | Q4: 971 | R4: 27 | S4: 30.688019 | T4: Pending | U4: 4.5805926 | V4: Air | W4: Route C | X4: 141.92028 | Y4: =IFERROR(H4/I4,0) | Z4: =IF(H4=0,"STOCKOUT",IF(Y4>=1.933,"Overstocked",IF(Y4<=0.3889,"Understocked","Healthy"))) | AA4: =IF(K4>8,"Delayed","On Time") | AB4: =MAX(0,K4-8) | AC4: =IF(T4="Pass",2,IF(T4="Pending",1,0))-(U4/5) | AD4: =IFERROR(X4/E4*1000,0)
A5: SKU3 | B5: skincare | C5: 61.163343 | D5: 68 | E5: 83 | F5: 7766.8364 | G5: Non-binary | H5: 23 | I5: 59 | J5: 13 | K5: 6 | L5: Carrier C | M5: 1.7295686 | N5: Supplier 5 | O5: Kolkata | P5: 24 | Q5: 937 | R5: 18 | S5: 35.624741 | T5: Fail | U5: 4.7466486 | V5: Rail | W5: Route A | X5: 254.77616 | Y5: =IFERROR(H5/I5,0) | Z5: =IF(H5=0,"STOCKOUT",IF(Y5>=1.933,"Overstocked",IF(Y5<=0.3889,"Understocked","Healthy"))) | AA5: =IF(K5>8,"Delayed","On Time") | AB5: =MAX(0,K5-8) | AC5: =IF(T5="Pass",2,IF(T5="Pending",1,0))-(U5/5) | AD5: =IFERROR(X5/E5*1000,0)
A6: SKU4 | B6: skincare | C6: 4.805496 | D6: 26 | E6: 871 | F6: 2686.5052 | G6: Non-binary | H6: 5 | I6: 56 | J6: 3 | K6: 8 | L6: Carrier A | M6: 3.8905479 | N6: Supplier 1 | O6: Delhi | P6: 5 | Q6: 414 | R6: 3 | S6: 92.065161 | T6: Fail | U6: 3.1455795 | V6: Air | W6: Route A | X6: 923.44063 | Y6: =IFERROR(H6/I6,0) | Z6: =IF(H6=0,"STOCKOUT",IF(Y6>=1.933,"Overstocked",IF(Y6<=0.3889,"Understocked","Healthy"))) | AA6: =IF(K6>8,"Delayed","On Time") | AB6: =MAX(0,K6-8) | AC6: =IF(T6="Pass",2,IF(T6="Pending",1,0))-(U6/5) | AD6: =IFERROR(X6/E6*1000,0)
A7: SKU5 | B7: haircare | C7: 1.699976 | D7: 87 | E7: 147 | F7: 2828.3487 | G7: Non-binary | H7: 90 | I7: 66 | J7: 27 | K7: 3 | L7: Carrier B | M7: 4.4440989 | N7: Supplier 4 | O7: Bangalore | P7: 10 | Q7: 104 | R7: 17 | S7: 56.766476 | T7: Fail | U7: 2.7791935 | V7: Road | W7: Route A | X7: 235.46124 | Y7: =IFERROR(H7/I7,0) | Z7: =IF(H7=0,"STOCKOUT",IF(Y7>=1.933,"Overstocked",IF(Y7<=0.3889,"Understocked","Healthy"))) | AA7: =IF(K7>8,"Delayed","On Time") | AB7: =MAX(0,K7-8) | AC7: =IF(T7="Pass",2,IF(T7="Pending",1,0))-(U7/5) | AD7: =IFERROR(X7/E7*1000,0)
A8: SKU6 | B8: skincare | C8: 4.0783329 | D8: 48 | E8: 65 | F8: 7823.4766 | G8: Male | H8: 11 | I8: 58 | J8: 15 | K8: 8 | L8: Carrier C | M8: 3.8807633 | N8: Supplier 3 | O8: Kolkata | P8: 14 | Q8: 314 | R8: 24 | S8: 1.0850686 | T8: Pending | U8: 1.0009106 | V8: Sea | W8: Route A | X8: 134.3691 | Y8: =IFERROR(H8/I8,0) | Z8: =IF(H8=0,"STOCKOUT",IF(Y8>=1.933,"Overstocked",IF(Y8<=0.3889,"Understocked","Healthy"))) | AA8: =IF(K8>8,"Delayed","On Time") | AB8: =MAX(0,K8-8) | AC8: =IF(T8="Pass",2,IF(T8="Pending",1,0))-(U8/5) | AD8: =IFERROR(X8/E8*1000,0)
A9: SKU7 | B9: cosmetics | C9: 42.958384 | D9: 59 | E9: 426 | F9: 8496.1038 | G9: Female | H9: 93 | I9: 11 | J9: 17 | K9: 1 | L9: Carrier B | M9: 2.3483388 | N9: Supplier 4 | O9: Bangalore | P9: 22 | Q9: 564 | R9: 1 | S9: 99.466109 | T9: Fail | U9: 0.39817719 | V9: Road | W9: Route C | X9: 802.05631 | Y9: =IFERROR(H9/I9,0) | Z9: =IF(H9=0,"STOCKOUT",IF(Y9>=1.933,"Overstocked",IF(Y9<=0.3889,"Understocked","Healthy"))) | AA9: =IF(K9>8,"Delayed","On Time") | AB9: =MAX(0,K9-8) | AC9: =IF(T9="Pass",2,IF(T9="Pending",1,0))-(U9/5) | AD9: =IFERROR(X9/E9*1000,0)
A10: SKU8 | B10: cosmetics | C10: 68.717597 | D10: 78 | E10: 150 | F10: 7517.3632 | G10: Female | H10: 5 | I10: 15 | J10: 10 | K10: 7 | L10: Carrier C | M10: 3.4047339 | N10: Supplier 4 | O10: Mumbai | P10: 13 | Q10: 769 | R10: 8 | S10: 11.423027 | T10: Pending | U10: 2.7098627 | V10: Sea | W10: Route B | X10: 505.55713 | Y10: =IFERROR(H10/I10,0) | Z10: =IF(H10=0,"STOCKOUT",IF(Y10>=1.933,"Overstocked",IF(Y10<=0.3889,"Understocked","Healthy"))) | AA10: =IF(K10>8,"Delayed","On Time") | AB10: =MAX(0,K10-8) | AC10: =IF(T10="Pass",2,IF(T10="Pending",1,0))-(U10/5) | AD10: =IFERROR(X10/E10*1000,0)
A11: SKU9 | B11: skincare | C11: 64.015733 | D11: 35 | E11: 980 | F11: 4971.146 | G11: Unknown | H11: 14 | I11: 83 | J11: 27 | K11: 1 | L11: Carrier A | M11: 7.1666453 | N11: Supplier 2 | O11: Chennai | P11: 29 | Q11: 963 | R11: 23 | S11: 47.957602 | T11: Pending | U11: 3.8446145 | V11: Rail | W11: Route B | X11: 995.92946 | Y11: =IFERROR(H11/I11,0) | Z11: =IF(H11=0,"STOCKOUT",IF(Y11>=1.933,"Overstocked",IF(Y11<=0.3889,"Understocked","Healthy"))) | AA11: =IF(K11>8,"Delayed","On Time") | AB11: =MAX(0,K11-8) | AC11: =IF(T11="Pass",2,IF(T11="Pending",1,0))-(U11/5) | AD11: =IFERROR(X11/E11*1000,0)
A12: SKU10 | B12: skincare | C12: 15.707796 | D12: 11 | E12: 996 | F12: 2330.9658 | G12: Non-binary | H12: 51 | I12: 80 | J12: 13 | K12: 2 | L12: Carrier C | M12: 8.6732112 | N12: Supplier 5 | O12: Kolkata | P12: 18 | Q12: 830 | R12: 5 | S12: 96.527353 | T12: Pass | U12: 1.7273139 | V12: Road | W12: Route B | X12: 806.10318 | Y12: =IFERROR(H12/I12,0) | Z12: =IF(H12=0,"STOCKOUT",IF(Y12>=1.933,"Overstocked",IF(Y12<=0.3889,"Understocked","Healthy"))) | AA12: =IF(K12>8,"Delayed","On Time") | AB12: =MAX(0,K12-8) | AC12: =IF(T12="Pass",2,IF(T12="Pending",1,0))-(U12/5) | AD12: =IFERROR(X12/E12*1000,0)
A13: SKU11 | B13: skincare | C13: 90.63546 | D13: 95 | E13: 960 | F13: 6099.9441 | G13: Female | H13: 46 | I13: 60 | J13: 23 | K13: 1 | L13: Carrier A | M13: 4.5239431 | N13: Supplier 2 | O13: Kolkata | P13: 28 | Q13: 362 | R13: 11 | S13: 27.592363 | T13: Pending | U13: 0.021169821 | V13: Air | W13: Route A | X13: 126.72303 | Y13: =IFERROR(H13/I13,0) | Z13: =IF(H13=0,"STOCKOUT",IF(Y13>=1.933,"Overstocked",IF(Y13<=0.3889,"Understocked","Healthy"))) | AA13: =IF(K13>8,"Delayed","On Time") | AB13: =MAX(0,K13-8) | AC13: =IF(T13="Pass",2,IF(T13="Pending",1,0))-(U13/5) | AD13: =IFERROR(X13/E13*1000,0)
... A101: SKU99 | B101: haircare | C101: 68.517833 | D101: 17 | E101: 627 | F101: 9185.1858 | G101: Unknown | H101: 55 | I101: 59 | J101: 8 | K101: 6 | L101: Carrier B | M101: 1.3110238 | N101: Supplier 2 | O101: Chennai | P101: 29 | Q101: 921 | R101: 2 | S101: 38.072899 | T101: Fail | U101: 0.34602729 | V101: Rail | W101: Route B | X101: 210.74301 | Y101: =IFERROR(H101/I101,0) | Z101: =IF(H101=0,"STOCKOUT",IF(Y101>=1.933,"Overstocked",IF(Y101<=0.3889,"Understocked","Healthy"))) | AA101: =IF(K101>8,"Delayed","On Time") | AB101: =MAX(0,K101-8) | AC101: =IF(T101="Pass",2,IF(T101="Pending",1,0))-(U101/5) | AD101: =IFERROR(X101/E101*1000,0)
